<robot name="pi_robot">
	<!-- * * * Link Definitions * * * -->
	<link name="base_link">
	<inertial>
            <mass value="10000000"/>
        </inertial>
		<visual>
			<geometry>
				<box size="2.56 2.32 0.68"/>
			</geometry>
			<material name="Cyan1">
				<color rgba="0 0.9 0.9 1.0"/>
			</material>
		</visual>
	</link>
	<link name="base_laser">
		<visual>
			<geometry>
				<cylinder radius="0.2" length="0.56"/>
			</geometry>
			<material name="Black1">
				<color rgba="0.2 0.2 0.2 1.0"/>
			</material>
		</visual>
	</link>
	<link name="cpu_link">
		<visual>
			<geometry>
				<box size="1.52 1.52 0.56"/>
			</geometry>
			<material name="Cyan2">
				<color rgba="0 0.7 0.7 1.0"/>
			</material>
		</visual>
	</link>
	<link name="upper_base_link">
		<visual>
			<geometry>
				<cylinder radius="0.68" length="0.8"/>
			</geometry>
			<material name="Cyan3">
				<color rgba="0 0.5 0.5 0"/>
			</material>
		</visual>
	</link>
	<link name="torso_link">
		<visual>
			<geometry>
				<cylinder radius="0.4" length="1.92"/>
			</geometry>
			<material name="Yellow2">
				<color rgba="0.8 0.8 0 1.0"/>
			</material>
		</visual>
	</link>
	<link name="head_pan_link">
		<visual>
			<geometry>
				<box size="0.4 0.36 0.36"/>
			</geometry>
			<material name="Green1">
				<color rgba="0 1 0 1.0"/>
			</material>
		</visual>
	</link>
	<link name="head_tilt_link">
		<visual>
			<geometry>
				<box size="0.24 0.304 0.32"/>
			</geometry>
			<material name="Green2">
				<color rgba="0.4 0.8 0 1.0"/>
			</material>
		</visual>
	</link>
	<link name="neck_link">
		<visual>
			<geometry>
				<box size="0.24 0.2 0.336"/>
			</geometry>
			<material name="Green3">
				<color rgba="0.4 0.5 0.4 1.0"/>
			</material>
		</visual>
	</link>
	<link name="head_link">
		<visual>
			<geometry>
				<box size="0.24 0.56 0.88"/>
			</geometry>
			<material name="Grey1">
				<color rgba="0.9 0.9 0.9 1.0"/>
			</material>
		</visual>
	</link>
	<!--	
	<link name="eyes_link"><visual><origin xyz="0.0 0 6" rpy="0 0 0"/> /><geometry><box size="0.01 0.04 0.01" /></geometry><material name="Blue2"><color rgba="0 0 0.7 1.0"/></material></visual></link>
-->
	<link name="antenna_link">
		<visual>
			<geometry>
				<cylinder radius="0.016" length="0.4"/>
			</geometry>
			<material name="Grey3">
				<color rgba="0.8 0.8 0.8 1.0"/>
			</material>
		</visual>
	</link>
	<link name="left_shoulder_link">
		<visual>
			<geometry>
				<box size="0.2 0.42 0.4"/>
			</geometry>
			<material name="Green1">
				<color rgba="0 1 0 1.0"/>
			</material>
		</visual>
	</link>
	<link name="right_shoulder_link">
		<visual>
			<geometry>
				<box size="0.2 0.42 0.4"/>
			</geometry>
			<material name="Green1">
				<color rgba="0 1 0 1.0"/>
			</material>
		</visual>
	</link>
	<link name="left_shoulder_forward_link">
		<visual>
			<geometry>
				<box size="0.24 0.4 0.24"/>
			</geometry>
			<material name="Blue1">
				<color rgba="0 0 0.9 1.0"/>
			</material>
		</visual>
	</link>
	<link name="right_shoulder_forward_link">
		<visual>
			<geometry>
				<box size="0.24 0.4 0.24"/>
			</geometry>
			<material name="Blue1">
				<color rgba="0 0 0.9 1.0"/>
			</material>
		</visual>
	</link>
	<link name="left_shoulder_up_link">
		<visual>
			<geometry>
				<box size="0.24 0.4 0.24"/>
			</geometry>
			<material name="Blue2">
				<color rgba="0 0 0.7 1.0"/>
			</material>
		</visual>
	</link>
	<link name="right_shoulder_up_link">
		<visual>
			<geometry>
				<box size="0.24 0.4 0.24"/>
			</geometry>
			<material name="Blue2">
				<color rgba="0 0 0.7 1.0"/>
			</material>
		</visual>
	</link>
	<link name="left_upper_arm_link">
		<visual>
			<geometry>
				<cylinder radius="0.06" length="0.4"/>
			</geometry>
			<material name="Grey1">
				<color rgba="0.9 0.9 0.9 1.0"/>
			</material>
		</visual>
	</link>
	<link name="right_upper_arm_link">
		<visual>
			<geometry>
				<cylinder radius="0.06" length="0.4"/>
			</geometry>
			<material name="Grey1">
				<color rgba="0.9 0.9 0.9 1.0"/>
			</material>
		</visual>
	</link>
	<link name="left_elbow_link">
		<visual>
			<geometry>
				<box size="0.28 0.28 0.4"/>
			</geometry>
			<material name="Blue2">
				<color rgba="0 0 0.7 1.0"/>
			</material>
		</visual>
	</link>
	<link name="right_elbow_link">
		<visual>
			<geometry>
				<box size="0.28 0.28 0.4"/>
			</geometry>
			<material name="Blue2">
				<color rgba="0 0 0.7 1.0"/>
			</material>
		</visual>
	</link>
	<link name="left_lower_arm_link">
		<visual>
			<geometry>
				<cylinder radius="0.06" length="0.88"/>
			</geometry>
			<material name="Grey1">
				<color rgba="0.9 0.9 0.9 1.0"/>
			</material>
		</visual>
	</link>
	<link name="right_lower_arm_link">
		<visual>
			<geometry>
				<cylinder radius="0.06" length="0.88"/>
			</geometry>
			<material name="Grey1">
				<color rgba="0.9 0.9 0.9 1.0"/>
			</material>
		</visual>
	</link>
	<link name="left_wrist_link">
		<visual>
			<geometry>
				<box size="0.24 0.4 0.24"/>
			</geometry>
			<material name="Blue2">
				<color rgba="0 0 0.7 1.0"/>
			</material>
		</visual>
	</link>
	<link name="right_wrist_link">
		<visual>
			<geometry>
				<box size="0.24 0.4 0.24"/>
			</geometry>
			<material name="Blue2">
				<color rgba="0 0 0.7 1.0"/>
			</material>
		</visual>
	</link>
	<link name="left_hand_link">
		<visual>
			<geometry>
				<box size="0.24 0.02 0.42"/>
			</geometry>
			<material name="Grey1">
				<color rgba="0.7 0.7 0.7 1.0"/>
			</material>
		</visual>
	</link>
	<link name="right_hand_link">
		<visual>
			<geometry>
				<box size="0.24 0.02 0.42"/>
			</geometry>
			<material name="Grey1">
				<color rgba="0.9 0.9 0.9 1.0"/>
			</material>
		</visual>
	</link>
	<!-- * * * Joint Definitions * * * -->
	<joint name="cpu_joint" type="fixed">
		<parent link="base_link"/>
		<child link="cpu_link"/>
		<origin xyz="0.0 0 0.6" rpy="0 0 0"/>
	</joint>
	<joint name="base_laser_joint" type="fixed">
		<parent link="base_link"/>
		<child link="base_laser"/>
		<origin xyz="1.4 0 0.2" rpy="0 0 0"/>
	</joint>
	<joint name="upper_base_joint" type="fixed">
		<parent link="cpu_link"/>
		<child link="upper_base_link"/>
		<origin xyz="0.0 0 0.45" rpy="0 0 0"/>
	</joint>
	<joint name="torso_joint" type="revolute">
		<parent link="upper_base_link"/>
		<child link="torso_link"/>
		<origin xyz="0.0 0 0.55" rpy="0 0 0"/>
		<axis xyz="0 0 1"/>
		<limit lower="-3.1416" upper="3.1416" effort="10" velocity="3"/>
	</joint>
<!--first-->
	<joint name="head_pan_servo" type="fixed">
		<parent link="torso_link"/>
		<child link="head_pan_link"/>
		<origin xyz="0.0 0 1.05" rpy="0 0 0"/>
	</joint>
	<!---->

	<joint name="head_pan_joint" type="revolute">
		<parent link="head_pan_link"/>
		<child link="head_tilt_link"/>
		<origin xyz="0.0 0 0.3" rpy="0 0 0"/>
		<axis xyz="0 0 1"/>
		<limit lower="-3.1416" upper="3.1416" effort="10" velocity="3"/>
	</joint>

	<joint name="head_tilt_joint" type="revolute">
		<parent link="head_tilt_link"/>
		<child link="neck_link"/>
		<origin xyz="0.0 0 0.32" rpy="0 0 0"/>
		<axis xyz="0 1 0"/>
		<limit lower="-1.57" upper="1.57" effort="10" velocity="3"/>
	</joint>
<!---->

	<joint name="neck_joint" type="fixed">
		<parent link="neck_link"/>
		<child link="head_link"/>
		<origin xyz="0.38 0 0.4" rpy="0 0 0"/> 
	</joint>
	<!--	
	<joint name="eyes_joint" type="fixed"><parent link="head_link" /><child link="eyes_link" /><origin xyz="0.0 0 6" rpy="0 0 0"/>0" /></joint>
-->
	<joint name="antenna_joint" type="fixed">
		<parent link="head_link"/>
		<child link="antenna_link"/>
		<origin xyz="0.0 0.275 0.45" rpy="0 0 0"/>
	</joint>

	<!-- Arms -->
<!--anpassung -->

	<joint name="left_shoulder_joint" type="fixed">
		<parent link="torso_link"/>
		<child link="left_shoulder_link"/>
		<origin xyz="0 -0.4 .76" rpy="0 0 0"/>
	</joint>

	<joint name="right_shoulder_joint" type="fixed">
		<parent link="torso_link"/>
		<child link="right_shoulder_link"/>
		<origin xyz="0 0.4 .76" rpy="0 0 0"/> 
	</joint>


	<joint name="left_shoulder_forward_joint" type="revolute">
		<parent link="left_shoulder_link"/>
		<child link="left_shoulder_forward_link"/>
		<origin xyz="0 -0.4 0" rpy="0 0 0"/>
		<limit lower="-1.57" upper="1.57" effort="10" velocity="3"/>
		<axis xyz="0 0 1"/>
	</joint>

	<joint name="right_shoulder_forward_joint" type="revolute">
		<parent link="right_shoulder_link"/>
		<child link="right_shoulder_forward_link"/>
		<origin xyz="0 0.4 0" rpy="0 0 0"/>
		<limit lower="-1.57" upper="1.57" effort="10" velocity="3"/>
		<axis xyz="0 0 1"/>
	</joint>

<!--anpassung -->


	<joint name="left_shoulder_up_joint" type="revolute">
		<parent link="left_shoulder_forward_link"/>
		<child link="left_shoulder_up_link"/>
		<origin xyz="0 -0.3 -0.14" rpy="1.575 0 0"/>
		<limit lower="-1.57" upper="1.57" effort="10" velocity="3"/>
		<axis xyz="0 1 0"/>
	</joint>

	<joint name="right_shoulder_up_joint" type="revolute">
		<parent link="right_shoulder_forward_link"/>
		<child link="right_shoulder_up_link"/>
		<origin xyz="0 0.3 -0.14" rpy="1.575 0 0"/>
		<limit lower="-1.57" upper="1.57" effort="10" velocity="3"/>
		<axis xyz="0 1 0"/>
	</joint>

	<joint name="left_upper_arm_joint" type="fixed">
		<parent link="left_shoulder_up_link"/>
		<child link="left_upper_arm_link"/>
		<origin xyz="0.0 0 -0.325" rpy="1.575 0 0"/>
	</joint>
	<joint name="right_upper_arm_joint" type="fixed">
		<parent link="right_shoulder_up_link"/>
		<child link="right_upper_arm_link"/>
		<origin xyz="0.0 0 -0.325" rpy="1.575 0 0"/>
	</joint>
	<joint name="left_elbow_joint" type="revolute">
		<parent link="left_upper_arm_link"/>
		<child link="left_elbow_link"/>
		<origin xyz="0.0 0 -0.325" rpy="0 0 0"/> 
		<limit lower="-3.146" upper="3.146" effort="10" velocity="3"/>
		<axis xyz="0 0 1"/>
	</joint>
	<joint name="right_elbow_joint" type="revolute">
		<parent link="right_upper_arm_link"/>
		<child link="right_elbow_link"/>
		<origin xyz="0.0 0 -0.325" rpy="0 0 0"/> 
		<limit lower="-3.146" upper="3.146" effort="10" velocity="3"/>
		<axis xyz="0 0 1"/>
	</joint>
	<joint name="left_lower_arm_joint" type="fixed">
		<parent link="left_elbow_link"/>
		<child link="left_lower_arm_link"/>
		<origin xyz="0.0 0 -0.325" rpy="0 0 0"/>
	</joint>
	<joint name="right_lower_arm_joint" type="fixed">
		<parent link="right_elbow_link"/>
		<child link="right_lower_arm_link"/>
		<origin xyz="0.0 0 -0.325" rpy="0 0 0"/>
	</joint>
	<joint name="left_wrist_joint" type="revolute">
		<parent link="left_lower_arm_link"/>
		<child link="left_wrist_link"/>
		<origin xyz="0.0 0 -0.325" rpy="1.575 0 0"/>
		<limit lower="-1.57" upper="1.57" effort="10" velocity="3"/>
		<axis xyz="1 0 0"/>
	</joint>
	<joint name="right_wrist_joint" type="revolute">
		<parent link="right_lower_arm_link"/>
		<child link="right_wrist_link"/>
		<origin xyz="0.0 0 -0.325" rpy="1.575 0 0"/>
		<limit lower="-1.57" upper="1.57" effort="10" velocity="3"/>
		<axis xyz="1 0 0"/>
	</joint>
	<joint name="left_hand_joint" type="fixed">
		<parent link="left_wrist_link"/>
		<child link="left_hand_link"/>
		<origin xyz="0.0 0 -0.325" rpy="1.575 0 0"/>
	</joint>
	<joint name="right_hand_joint" type="fixed">
		<parent link="right_wrist_link"/>
		<child link="right_hand_link"/>
		<origin xyz="0.0 0 -0.325" rpy="1.575 0 0"/>
	</joint>
</robot>
