<?xml version="1.0" ?>
<!-- =================================================================================== -->
<!-- |    This document was autogenerated by xacro from pr2_no_arms.urdf.xacro         | -->
<!-- |    EDITING THIS FILE BY HAND IS NOT RECOMMENDED                                 | -->
<!-- =================================================================================== -->
<robot name="pr2" xmlns:controller="http://playerstage.sourceforge.net/gazebo/xmlschema/#controller" xmlns:interface="http://playerstage.sourceforge.net/gazebo/xmlschema/#interface" xmlns:sensor="http://playerstage.sourceforge.net/gazebo/xmlschema/#sensor" xmlns:xacro="http://playerstage.sourceforge.net/gazebo/xmlschema/#interface">
  <!-- DATA SOURCES -->
  <!-- all link offsets, CG, limits are obtained from Function Engineering spreadsheet 090224_link_data.xls unless stated otherwise -->
  <!-- all link geometry sizes are obtained from Function provided CAD model unless stated otherwise -->
  <!-- all simplified collision geometry are hand approximated from CAD model, sometimes from respective bounding boxes -->
  <!-- This is the 'effective' wheel radius. Wheel radius for uncompressed wheel is 0.079.  mp 20080801 -->
  <gazebo>
    <plugin filename="libgazebo_ros_controller_manager.so" name="gazebo_ros_controller_manager">
      <alwaysOn>true</alwaysOn>
      <updateRate>1000.0</updateRate>
    </plugin>
    <plugin filename="libgazebo_ros_power_monitor.so" name="gazebo_ros_power_monitor_controller">
      <alwaysOn>true</alwaysOn>
      <updateRate>1.0</updateRate>
      <timeout>5</timeout>
      <powerStateTopic>power_state</powerStateTopic>
      <powerStateRate>10.0</powerStateRate>
      <fullChargeCapacity>87.78</fullChargeCapacity>
      <dischargeRate>-474</dischargeRate>
      <chargeRate>525</chargeRate>
      <dischargeVoltage>15.52</dischargeVoltage>
      <chargeVoltage>16.41</chargeVoltage>
    </plugin>
  </gazebo>
  <material name="Blue">
    <color rgba="0.0 0.0 0.8 1.0"/>
  </material>
  <material name="Green">
    <color rgba="0.0 0.8 0.0 1.0"/>
  </material>
  <material name="Grey">
    <color rgba="0.7 0.7 0.7 1.0"/>
  </material>
  <material name="Grey2">
    <color rgba="0.9 0.9 0.9 1.0"/>
  </material>
  <material name="Red">
    <color rgba="0.8 0.0 0.0 1.0"/>
  </material>
  <material name="White">
    <color rgba="1.0 1.0 1.0 1.0"/>
  </material>
  <material name="Black">
    <color rgba="0.1 0.1 0.1 1.0"/>
  </material>
  <material name="LightGrey">
    <color rgba="0.6 0.6 0.6 1.0"/>
  </material>
  <material name="Caster">
    <texture filename="/pr2_description/materials/textures/pr2_caster_texture.png"/>
  </material>
  <material name="Wheel_l">
    <texture filename="/pr2_description/materials/textures/pr2_wheel_left.png"/>
  </material>
  <material name="Wheel_r">
    <texture filename="/pr2_description/materials/textures/pr2_wheel_right.png"/>
  </material>
  <material name="RollLinks">
    <texture filename="/pr2_description/materials/textures/pr2_wheel_left.png"/>
  </material>
  <!-- Now we can start using the macros included above to define the actual PR2 -->
  <link name="base_link">
    <inertial>
      <mass value="116.0"/>
      <origin xyz="-0.061 0.0 0.1465"/>
      <inertia ixx="5.652232699207" ixy="-0.009719934438" ixz="1.293988226423" iyy="5.669473158652" iyz="-0.007379583694" izz="3.683196351726"/>
    </inertial>
    <visual>
      <origin rpy="0 0 0" xyz="0 0 0"/>
      <geometry>
        <mesh filename="/pr2_description/meshes/base_v0/base.fbx"/>
      </geometry>
      <material name="White"/>
    </visual>
    <collision>
      <origin rpy="0 0 0" xyz="0 0 0"/>
      <geometry>
        <mesh filename="/pr2_description/meshes/base_v0/base_L.fbx"/>
      </geometry>
    </collision>
  </link>
  <!-- base_footprint is a fictitious link(frame) that is on the ground right below base_link origin,
         navigation stack dedpends on this frame -->
  <link name="base_footprint">
    <inertial>
      <mass value="1.0"/>
      <origin xyz="0 0 0"/>
      <inertia ixx="0.01" ixy="0.0" ixz="0.0" iyy="0.01" iyz="0.0" izz="0.01"/>
    </inertial>
    <visual>
      <origin rpy="0 0 0" xyz="0 0 0"/>
      <geometry>
        <box size="0.01 0.01 0.01"/>
      </geometry>
      <material name="White"/>
    </visual>
    <collision>
      <!-- represent base collision with a simple rectangular model, positioned by base_size_z s.t. top
             surface of the collision box matches the top surface of the PR2 base -->
      <origin rpy="0 0 0" xyz="0 0 0.071"/>
      <geometry>
        <box size="0.001 0.001 0.001"/>
      </geometry>
    </collision>
  </link>
  <joint name="base_footprint_joint" type="fixed">
    <origin rpy="0 0 0" xyz="0 0 0.051"/>
    <child link="base_link"/>
    <parent link="base_footprint"/>
  </joint>
  <!-- visualize bellow -->
  <link name="base_bellow_link">
    <inertial>
      <mass value="1.0"/>
      <origin xyz="0 0 0"/>
      <inertia ixx="0.01" ixy="0.0" ixz="0.0" iyy="0.01" iyz="0.0" izz="0.01"/>
    </inertial>
    <visual>
      <origin rpy="0 0 0" xyz="0 0 0"/>
      <geometry>
        <box size="0.05 0.37 0.3"/>
      </geometry>
      <material name="Black"/>
    </visual>
    <collision>
      <origin rpy="0 0 0" xyz="0 0 0"/>
      <geometry>
        <box size="0.05 0.37 0.3"/>
      </geometry>
    </collision>
  </link>
  <joint name="base_bellow_joint" type="fixed">
    <origin rpy="0 0 0" xyz="-0.29 0 0.8"/>
    <parent link="base_link"/>
    <child link="base_bellow_link"/>
  </joint>
  <joint name="base_laser_joint" type="fixed">
    <axis xyz="0 1 0"/>
    <origin rpy="0 0 0" xyz="0.275 0.0 0.252"/>
    <parent link="base_link"/>
    <child link="base_laser_link"/>
  </joint>
  <link name="base_laser_link" type="laser">
    <inertial>
      <mass value="0.001"/>
      <origin rpy="0 0 0" xyz="0 0 0"/>
      <inertia ixx="0.0001" ixy="0" ixz="0" iyy="0.000001" iyz="0" izz="0.0001"/>
    </inertial>
  </link>
  <gazebo reference="base_laser_link">
    <sensor name="base_laser" type="ray">
      <always_on>true</always_on>
      <update_rate>20</update_rate>
      <pose>0 0 0 0 0 0</pose>
      <visualize>false</visualize>
      <ray>
        <scan>
          <horizontal>
            <samples>640</samples>
            <resolution>1</resolution>
            <min_angle>-2.2689</min_angle>
            <max_angle>2.2689</max_angle>
          </horizontal>
        </scan>
        <range>
          <min>0.08</min>
          <max>10.0</max>
          <resolution>0.01</resolution>
        </range>
      </ray>
      <plugin filename="libgazebo_ros_laser.so" name="gazebo_ros_base_laser_controller">
        <gaussianNoise>0.005</gaussianNoise>
        <alwaysOn>true</alwaysOn>
        <updateRate>20</updateRate>
        <topicName>base_scan</topicName>
        <frameName>base_laser_link</frameName>
        <hokuyoMinIntensity>101</hokuyoMinIntensity>
      </plugin>
    </sensor>
  </gazebo>
  <joint name="fl_caster_rotation_joint" type="continuous">
    <axis xyz="0 0 1"/>
    <limit effort="6.5" velocity="10"/>
    <!-- alpha tested velocity and effort limits -->
    <safety_controller k_velocity="10"/>
    <calibration rising="-0.785398163397"/>
    <dynamics damping="1.0" friction="0.0"/>
    <origin rpy="0 0 0" xyz="0.2246 0.2246 0.0282"/>
    <parent link="base_link"/>
    <child link="fl_caster_rotation_link"/>
  </joint>
  <link name="fl_caster_rotation_link">
    <inertial>
      <mass value="3.473082"/>
      <origin xyz="0 0 0.07"/>
      <inertia ixx="0.012411765597" ixy="-0.000711733678" ixz="0.00050272983" iyy="0.015218160428" iyz="-0.000004273467" izz="0.011763977943"/>
    </inertial>
    <visual>
      <origin rpy="0 0 0" xyz="0 0 0"/>
      <geometry>
        <mesh filename="/pr2_description/meshes/base_v0/caster.fbx"/>
      </geometry>
      <material name="Caster"/>
    </visual>
    <collision>
      <origin rpy="0 0 0" xyz="0 0 0"/>
      <geometry>
        <mesh filename="/pr2_description/meshes/base_v0/caster_L.fbx"/>
      </geometry>
    </collision>
  </link>
  <transmission name="fl_caster_rotation_trans" type="pr2_mechanism_model/SimpleTransmission">
    <actuator name="fl_caster_rotation_motor"/>
    <joint name="fl_caster_rotation_joint"/>
    <mechanicalReduction>-79.2380952381</mechanicalReduction>
  </transmission>
  <joint name="fl_caster_l_wheel_joint" type="continuous">
    <axis xyz="0 1 0"/>
    <limit effort="7" velocity="15"/>
    <!-- alpha tested effort and velocity limits -->
    <safety_controller k_velocity="10"/>
    <dynamics damping="1.0" friction="0.0"/>
    <origin rpy="0 0 0" xyz="0 0.049 0"/>
    <parent link="fl_caster_rotation_link"/>
    <child link="fl_caster_l_wheel_link"/>
  </joint>
  <link name="fl_caster_l_wheel_link">
    <inertial>
      <mass value="0.44036"/>
      <origin xyz="0 0 0"/>
      <inertia ixx="0.012411765597" ixy="-0.000711733678" ixz="0.00050272983" iyy="0.015218160428" iyz="-0.000004273467" izz="0.011763977943"/>
    </inertial>
    <visual>
      <origin rpy="0 0 0" xyz="0 0 0"/>
      <geometry>
        <mesh filename="/pr2_description/meshes/base_v0/wheel.fbx"/>
      </geometry>
      <material name="Wheel_l"/>
    </visual>
    <collision>
      <origin rpy="1.57079632679 0 0" xyz="0 0 0"/>
      <!-- rotation because cyl. geom primitive has symmetry axis in +x direction -->
      <geometry>
        <cylinder length="0.034" radius="0.074792"/>
      </geometry>
    </collision>
  </link>
  <gazebo reference="fl_caster_l_wheel_link">
    <mu1 value="100.0"/>
    <mu2 value="100.0"/>
    <kp value="1000000.0"/>
    <kd value="1.0"/>
    <maxVel value="100.0"/>
    <minDepth value="0.0"/>
  </gazebo>
  <transmission name="fl_caster_l_wheel_trans" type="pr2_mechanism_model/SimpleTransmission">
    <actuator name="fl_caster_l_wheel_motor"/>
    <joint name="fl_caster_l_wheel_joint"/>
    <mechanicalReduction>79.2380952381</mechanicalReduction>
  </transmission>
  <joint name="fl_caster_r_wheel_joint" type="continuous">
    <axis xyz="0 1 0"/>
    <limit effort="7" velocity="15"/>
    <!-- alpha tested effort and velocity limits -->
    <safety_controller k_velocity="10"/>
    <dynamics damping="1.0" friction="0.0"/>
    <origin rpy="0 0 0" xyz="0 -0.049 0"/>
    <parent link="fl_caster_rotation_link"/>
    <child link="fl_caster_r_wheel_link"/>
  </joint>
  <link name="fl_caster_r_wheel_link">
    <inertial>
      <mass value="0.44036"/>
      <origin xyz="0 0 0"/>
      <inertia ixx="0.012411765597" ixy="-0.000711733678" ixz="0.00050272983" iyy="0.015218160428" iyz="-0.000004273467" izz="0.011763977943"/>
    </inertial>
    <visual>
      <origin rpy="0 0 0" xyz="0 0 0"/>
      <geometry>
        <mesh filename="/pr2_description/meshes/base_v0/wheel.fbx"/>
      </geometry>
      <material name="Wheel_r"/>
    </visual>
    <collision>
      <origin rpy="1.57079632679 0 0" xyz="0 0 0"/>
      <!-- rotation because cyl. geom primitive has symmetry axis in +x direction -->
      <geometry>
        <cylinder length="0.034" radius="0.074792"/>
      </geometry>
    </collision>
  </link>
  <gazebo reference="fl_caster_r_wheel_link">
    <mu1 value="100.0"/>
    <mu2 value="100.0"/>
    <kp value="1000000.0"/>
    <kd value="1.0"/>
    <maxVel value="100.0"/>
    <minDepth value="0.0"/>
  </gazebo>
  <transmission name="fl_caster_r_wheel_trans" type="pr2_mechanism_model/SimpleTransmission">
    <actuator name="fl_caster_r_wheel_motor"/>
    <joint name="fl_caster_r_wheel_joint"/>
    <mechanicalReduction>-79.2380952381</mechanicalReduction>
  </transmission>
  <gazebo reference="fl_caster_rotation_link">
    <material value="PR2/caster_texture"/>
  </gazebo>
  <joint name="fr_caster_rotation_joint" type="continuous">
    <axis xyz="0 0 1"/>
    <limit effort="6.5" velocity="10"/>
    <!-- alpha tested velocity and effort limits -->
    <safety_controller k_velocity="10"/>
    <calibration rising="-0.785398163397"/>
    <dynamics damping="1.0" friction="0.0"/>
    <origin rpy="0 0 0" xyz="0.2246 -0.2246 0.0282"/>
    <parent link="base_link"/>
    <child link="fr_caster_rotation_link"/>
  </joint>
  <link name="fr_caster_rotation_link">
    <inertial>
      <mass value="3.473082"/>
      <origin xyz="0 0 0.07"/>
      <inertia ixx="0.012411765597" ixy="-0.000711733678" ixz="0.00050272983" iyy="0.015218160428" iyz="-0.000004273467" izz="0.011763977943"/>
    </inertial>
    <visual>
      <origin rpy="0 0 0" xyz="0 0 0"/>
      <geometry>
        <mesh filename="/pr2_description/meshes/base_v0/caster.fbx"/>
      </geometry>
      <material name="Caster"/>
    </visual>
    <collision>
      <origin rpy="0 0 0" xyz="0 0 0"/>
      <geometry>
        <mesh filename="/pr2_description/meshes/base_v0/caster_L.fbx"/>
      </geometry>
    </collision>
  </link>
  <transmission name="fr_caster_rotation_trans" type="pr2_mechanism_model/SimpleTransmission">
    <actuator name="fr_caster_rotation_motor"/>
    <joint name="fr_caster_rotation_joint"/>
    <mechanicalReduction>-79.2380952381</mechanicalReduction>
  </transmission>
  <joint name="fr_caster_l_wheel_joint" type="continuous">
    <axis xyz="0 1 0"/>
    <limit effort="7" velocity="15"/>
    <!-- alpha tested effort and velocity limits -->
    <safety_controller k_velocity="10"/>
    <dynamics damping="1.0" friction="0.0"/>
    <origin rpy="0 0 0" xyz="0 0.049 0"/>
    <parent link="fr_caster_rotation_link"/>
    <child link="fr_caster_l_wheel_link"/>
  </joint>
  <link name="fr_caster_l_wheel_link">
    <inertial>
      <mass value="0.44036"/>
      <origin xyz="0 0 0"/>
      <inertia ixx="0.012411765597" ixy="-0.000711733678" ixz="0.00050272983" iyy="0.015218160428" iyz="-0.000004273467" izz="0.011763977943"/>
    </inertial>
    <visual>
      <origin rpy="0 0 0" xyz="0 0 0"/>
      <geometry>
        <mesh filename="/pr2_description/meshes/base_v0/wheel.fbx"/>
      </geometry>
      <material name="Wheel_l"/>
    </visual>
    <collision>
      <origin rpy="1.57079632679 0 0" xyz="0 0 0"/>
      <!-- rotation because cyl. geom primitive has symmetry axis in +x direction -->
      <geometry>
        <cylinder length="0.034" radius="0.074792"/>
      </geometry>
    </collision>
  </link>
  <gazebo reference="fr_caster_l_wheel_link">
    <mu1 value="100.0"/>
    <mu2 value="100.0"/>
    <kp value="1000000.0"/>
    <kd value="1.0"/>
    <maxVel value="100.0"/>
    <minDepth value="0.0"/>
  </gazebo>
  <transmission name="fr_caster_l_wheel_trans" type="pr2_mechanism_model/SimpleTransmission">
    <actuator name="fr_caster_l_wheel_motor"/>
    <joint name="fr_caster_l_wheel_joint"/>
    <mechanicalReduction>79.2380952381</mechanicalReduction>
  </transmission>
  <joint name="fr_caster_r_wheel_joint" type="continuous">
    <axis xyz="0 1 0"/>
    <limit effort="7" velocity="15"/>
    <!-- alpha tested effort and velocity limits -->
    <safety_controller k_velocity="10"/>
    <dynamics damping="1.0" friction="0.0"/>
    <origin rpy="0 0 0" xyz="0 -0.049 0"/>
    <parent link="fr_caster_rotation_link"/>
    <child link="fr_caster_r_wheel_link"/>
  </joint>
  <link name="fr_caster_r_wheel_link">
    <inertial>
      <mass value="0.44036"/>
      <origin xyz="0 0 0"/>
      <inertia ixx="0.012411765597" ixy="-0.000711733678" ixz="0.00050272983" iyy="0.015218160428" iyz="-0.000004273467" izz="0.011763977943"/>
    </inertial>
    <visual>
      <origin rpy="0 0 0" xyz="0 0 0"/>
      <geometry>
        <mesh filename="/pr2_description/meshes/base_v0/wheel.fbx"/>
      </geometry>
      <material name="Wheel_r"/>
    </visual>
    <collision>
      <origin rpy="1.57079632679 0 0" xyz="0 0 0"/>
      <!-- rotation because cyl. geom primitive has symmetry axis in +x direction -->
      <geometry>
        <cylinder length="0.034" radius="0.074792"/>
      </geometry>
    </collision>
  </link>
  <gazebo reference="fr_caster_r_wheel_link">
    <mu1 value="100.0"/>
    <mu2 value="100.0"/>
    <kp value="1000000.0"/>
    <kd value="1.0"/>
    <maxVel value="100.0"/>
    <minDepth value="0.0"/>
  </gazebo>
  <transmission name="fr_caster_r_wheel_trans" type="pr2_mechanism_model/SimpleTransmission">
    <actuator name="fr_caster_r_wheel_motor"/>
    <joint name="fr_caster_r_wheel_joint"/>
    <mechanicalReduction>-79.2380952381</mechanicalReduction>
  </transmission>
  <gazebo reference="fr_caster_rotation_link">
    <material value="PR2/caster_texture"/>
  </gazebo>
  <joint name="bl_caster_rotation_joint" type="continuous">
    <axis xyz="0 0 1"/>
    <limit effort="6.5" velocity="10"/>
    <!-- alpha tested velocity and effort limits -->
    <safety_controller k_velocity="10"/>
    <calibration rising="2.35619449019"/>
    <dynamics damping="1.0" friction="0.0"/>
    <origin rpy="0 0 0" xyz="-0.2246 0.2246 0.0282"/>
    <parent link="base_link"/>
    <child link="bl_caster_rotation_link"/>
  </joint>
  <link name="bl_caster_rotation_link">
    <inertial>
      <mass value="3.473082"/>
      <origin xyz="0 0 0.07"/>
      <inertia ixx="0.012411765597" ixy="-0.000711733678" ixz="0.00050272983" iyy="0.015218160428" iyz="-0.000004273467" izz="0.011763977943"/>
    </inertial>
    <visual>
      <origin rpy="0 0 0" xyz="0 0 0"/>
      <geometry>
        <mesh filename="/pr2_description/meshes/base_v0/caster.fbx"/>
      </geometry>
      <material name="Caster"/>
    </visual>
    <collision>
      <origin rpy="0 0 0" xyz="0 0 0"/>
      <geometry>
        <mesh filename="/pr2_description/meshes/base_v0/caster_L.fbx"/>
      </geometry>
    </collision>
  </link>
  <transmission name="bl_caster_rotation_trans" type="pr2_mechanism_model/SimpleTransmission">
    <actuator name="bl_caster_rotation_motor"/>
    <joint name="bl_caster_rotation_joint"/>
    <mechanicalReduction>-79.2380952381</mechanicalReduction>
  </transmission>
  <joint name="bl_caster_l_wheel_joint" type="continuous">
    <axis xyz="0 1 0"/>
    <limit effort="7" velocity="15"/>
    <!-- alpha tested effort and velocity limits -->
    <safety_controller k_velocity="10"/>
    <dynamics damping="1.0" friction="0.0"/>
    <origin rpy="0 0 0" xyz="0 0.049 0"/>
    <parent link="bl_caster_rotation_link"/>
    <child link="bl_caster_l_wheel_link"/>
  </joint>
  <link name="bl_caster_l_wheel_link">
    <inertial>
      <mass value="0.44036"/>
      <origin xyz="0 0 0"/>
      <inertia ixx="0.012411765597" ixy="-0.000711733678" ixz="0.00050272983" iyy="0.015218160428" iyz="-0.000004273467" izz="0.011763977943"/>
    </inertial>
    <visual>
      <origin rpy="0 0 0" xyz="0 0 0"/>
      <geometry>
        <mesh filename="/pr2_description/meshes/base_v0/wheel.fbx"/>
      </geometry>
      <material name="Wheel_l"/>
    </visual>
    <collision>
      <origin rpy="1.57079632679 0 0" xyz="0 0 0"/>
      <!-- rotation because cyl. geom primitive has symmetry axis in +x direction -->
      <geometry>
        <cylinder length="0.034" radius="0.074792"/>
      </geometry>
    </collision>
  </link>
  <gazebo reference="bl_caster_l_wheel_link">
    <mu1 value="100.0"/>
    <mu2 value="100.0"/>
    <kp value="1000000.0"/>
    <kd value="1.0"/>
    <maxVel value="100.0"/>
    <minDepth value="0.0"/>
  </gazebo>
  <transmission name="bl_caster_l_wheel_trans" type="pr2_mechanism_model/SimpleTransmission">
    <actuator name="bl_caster_l_wheel_motor"/>
    <joint name="bl_caster_l_wheel_joint"/>
    <mechanicalReduction>79.2380952381</mechanicalReduction>
  </transmission>
  <joint name="bl_caster_r_wheel_joint" type="continuous">
    <axis xyz="0 1 0"/>
    <limit effort="7" velocity="15"/>
    <!-- alpha tested effort and velocity limits -->
    <safety_controller k_velocity="10"/>
    <dynamics damping="1.0" friction="0.0"/>
    <origin rpy="0 0 0" xyz="0 -0.049 0"/>
    <parent link="bl_caster_rotation_link"/>
    <child link="bl_caster_r_wheel_link"/>
  </joint>
  <link name="bl_caster_r_wheel_link">
    <inertial>
      <mass value="0.44036"/>
      <origin xyz="0 0 0"/>
      <inertia ixx="0.012411765597" ixy="-0.000711733678" ixz="0.00050272983" iyy="0.015218160428" iyz="-0.000004273467" izz="0.011763977943"/>
    </inertial>
    <visual>
      <origin rpy="0 0 0" xyz="0 0 0"/>
      <geometry>
        <mesh filename="/pr2_description/meshes/base_v0/wheel.fbx"/>
      </geometry>
      <material name="Wheel_r"/>
    </visual>
    <collision>
      <origin rpy="1.57079632679 0 0" xyz="0 0 0"/>
      <!-- rotation because cyl. geom primitive has symmetry axis in +x direction -->
      <geometry>
        <cylinder length="0.034" radius="0.074792"/>
      </geometry>
    </collision>
  </link>
  <gazebo reference="bl_caster_r_wheel_link">
    <mu1 value="100.0"/>
    <mu2 value="100.0"/>
    <kp value="1000000.0"/>
    <kd value="1.0"/>
    <maxVel value="100.0"/>
    <minDepth value="0.0"/>
  </gazebo>
  <transmission name="bl_caster_r_wheel_trans" type="pr2_mechanism_model/SimpleTransmission">
    <actuator name="bl_caster_r_wheel_motor"/>
    <joint name="bl_caster_r_wheel_joint"/>
    <mechanicalReduction>-79.2380952381</mechanicalReduction>
  </transmission>
  <gazebo reference="bl_caster_rotation_link">
    <material value="PR2/caster_texture"/>
  </gazebo>
  <joint name="br_caster_rotation_joint" type="continuous">
    <axis xyz="0 0 1"/>
    <limit effort="6.5" velocity="10"/>
    <!-- alpha tested velocity and effort limits -->
    <safety_controller k_velocity="10"/>
    <calibration rising="2.35619449019"/>
    <dynamics damping="1.0" friction="0.0"/>
    <origin rpy="0 0 0" xyz="-0.2246 -0.2246 0.0282"/>
    <parent link="base_link"/>
    <child link="br_caster_rotation_link"/>
  </joint>
  <link name="br_caster_rotation_link">
    <inertial>
      <mass value="3.473082"/>
      <origin xyz="0 0 0.07"/>
      <inertia ixx="0.012411765597" ixy="-0.000711733678" ixz="0.00050272983" iyy="0.015218160428" iyz="-0.000004273467" izz="0.011763977943"/>
    </inertial>
    <visual>
      <origin rpy="0 0 0" xyz="0 0 0"/>
      <geometry>
        <mesh filename="/pr2_description/meshes/base_v0/caster.fbx"/>
      </geometry>
      <material name="Caster"/>
    </visual>
    <collision>
      <origin rpy="0 0 0" xyz="0 0 0"/>
      <geometry>
        <mesh filename="/pr2_description/meshes/base_v0/caster_L.fbx"/>
      </geometry>
    </collision>
  </link>
  <transmission name="br_caster_rotation_trans" type="pr2_mechanism_model/SimpleTransmission">
    <actuator name="br_caster_rotation_motor"/>
    <joint name="br_caster_rotation_joint"/>
    <mechanicalReduction>-79.2380952381</mechanicalReduction>
  </transmission>
  <joint name="br_caster_l_wheel_joint" type="continuous">
    <axis xyz="0 1 0"/>
    <limit effort="7" velocity="15"/>
    <!-- alpha tested effort and velocity limits -->
    <safety_controller k_velocity="10"/>
    <dynamics damping="1.0" friction="0.0"/>
    <origin rpy="0 0 0" xyz="0 0.049 0"/>
    <parent link="br_caster_rotation_link"/>
    <child link="br_caster_l_wheel_link"/>
  </joint>
  <link name="br_caster_l_wheel_link">
    <inertial>
      <mass value="0.44036"/>
      <origin xyz="0 0 0"/>
      <inertia ixx="0.012411765597" ixy="-0.000711733678" ixz="0.00050272983" iyy="0.015218160428" iyz="-0.000004273467" izz="0.011763977943"/>
    </inertial>
    <visual>
      <origin rpy="0 0 0" xyz="0 0 0"/>
      <geometry>
        <mesh filename="/pr2_description/meshes/base_v0/wheel.fbx"/>
      </geometry>
      <material name="Wheel_l"/>
    </visual>
    <collision>
      <origin rpy="1.57079632679 0 0" xyz="0 0 0"/>
      <!-- rotation because cyl. geom primitive has symmetry axis in +x direction -->
      <geometry>
        <cylinder length="0.034" radius="0.074792"/>
      </geometry>
    </collision>
  </link>
  <gazebo reference="br_caster_l_wheel_link">
    <mu1 value="100.0"/>
    <mu2 value="100.0"/>
    <kp value="1000000.0"/>
    <kd value="1.0"/>
    <maxVel value="100.0"/>
    <minDepth value="0.0"/>
  </gazebo>
  <transmission name="br_caster_l_wheel_trans" type="pr2_mechanism_model/SimpleTransmission">
    <actuator name="br_caster_l_wheel_motor"/>
    <joint name="br_caster_l_wheel_joint"/>
    <mechanicalReduction>79.2380952381</mechanicalReduction>
  </transmission>
  <joint name="br_caster_r_wheel_joint" type="continuous">
    <axis xyz="0 1 0"/>
    <limit effort="7" velocity="15"/>
    <!-- alpha tested effort and velocity limits -->
    <safety_controller k_velocity="10"/>
    <dynamics damping="1.0" friction="0.0"/>
    <origin rpy="0 0 0" xyz="0 -0.049 0"/>
    <parent link="br_caster_rotation_link"/>
    <child link="br_caster_r_wheel_link"/>
  </joint>
  <link name="br_caster_r_wheel_link">
    <inertial>
      <mass value="0.44036"/>
      <origin xyz="0 0 0"/>
      <inertia ixx="0.012411765597" ixy="-0.000711733678" ixz="0.00050272983" iyy="0.015218160428" iyz="-0.000004273467" izz="0.011763977943"/>
    </inertial>
    <visual>
      <origin rpy="0 0 0" xyz="0 0 0"/>
      <geometry>
        <mesh filename="/pr2_description/meshes/base_v0/wheel.fbx"/>
      </geometry>
      <material name="Wheel_r"/>
    </visual>
    <collision>
      <origin rpy="1.57079632679 0 0" xyz="0 0 0"/>
      <!-- rotation because cyl. geom primitive has symmetry axis in +x direction -->
      <geometry>
        <cylinder length="0.034" radius="0.074792"/>
      </geometry>
    </collision>
  </link>
  <gazebo reference="br_caster_r_wheel_link">
    <mu1 value="100.0"/>
    <mu2 value="100.0"/>
    <kp value="1000000.0"/>
    <kd value="1.0"/>
    <maxVel value="100.0"/>
    <minDepth value="0.0"/>
  </gazebo>
  <transmission name="br_caster_r_wheel_trans" type="pr2_mechanism_model/SimpleTransmission">
    <actuator name="br_caster_r_wheel_motor"/>
    <joint name="br_caster_r_wheel_joint"/>
    <mechanicalReduction>-79.2380952381</mechanicalReduction>
  </transmission>
  <gazebo reference="br_caster_rotation_link">
    <material value="PR2/caster_texture"/>
  </gazebo>
  <gazebo reference="base_link">
    <selfCollide>false</selfCollide>
    <sensor name="base_contact_sensor" type="contact">
      <always_on>true</always_on>
      <update_rate>100.0</update_rate>
      <contact>
        <collision>base_link_collision</collision>
      </contact>
      <plugin filename="libgazebo_ros_bumper.so" name="base_gazebo_ros_bumper_controller">
        <alwaysOn>true</alwaysOn>
        <updateRate>100.0</updateRate>
        <bumperTopicName>base_bumper</bumperTopicName>
        <frameName>world</frameName>
      </plugin>
    </sensor>
  </gazebo>
  <gazebo reference="base_bellow_link">
    <material value="PR2/Black"/>
  </gazebo>
  <gazebo>
    <plugin filename="libgazebo_ros_p3d.so" name="p3d_base_controller">
      <alwaysOn>true</alwaysOn>
      <updateRate>100.0</updateRate>
      <bodyName>base_link</bodyName>
      <topicName>base_pose_ground_truth</topicName>
      <gaussianNoise>0.01</gaussianNoise>
      <frameName>map</frameName>
      <xyzOffsets>0 0 0</xyzOffsets>
      <rpyOffsets>0 0 0</rpyOffsets>
    </plugin>
  </gazebo>
  <joint name="torso_lift_joint" type="prismatic">
    <axis xyz="0 0 1"/>
    <limit effort="10000" lower="0.0" upper="0.33" velocity="0.013"/>
    <!-- alpha tested velocity and effort limits -->
    <safety_controller k_position="100" k_velocity="2000000" soft_lower_limit="0.0115" soft_upper_limit="0.325"/>
    <calibration falling="0.00475"/>
    <dynamics damping="20000.0"/>
    <origin rpy="0 0 0" xyz="-0.05 0 0.739675"/>
    <parent link="base_link"/>
    <child link="torso_lift_link"/>
  </joint>
  <link name="torso_lift_link">
    <inertial>
      <mass value="36.248046"/>
      <origin xyz="-0.1 0 -0.0885"/>
      <inertia ixx="2.771653750257" ixy="0.004284522609" ixz="-0.160418504506" iyy="2.510019507959" iyz="0.029664468704" izz="0.526432355569"/>
    </inertial>
    <visual>
      <origin rpy="0 0 0" xyz="0 0 0"/>
      <geometry>
        <mesh filename="/pr2_description/meshes/torso_v0/torso_lift.fbx"/>
      </geometry>
      <material name="Grey2"/>
    </visual>
    <collision name="torso_lift_collision">
      <origin rpy="0 0 0" xyz="0 0 0"/>
      <geometry>
        <mesh filename="/pr2_description/meshes/torso_v0/torso_lift_L.fbx"/>
      </geometry>
    </collision>
  </link>
  <joint name="l_torso_lift_side_plate_joint" type="fixed">
    <origin xyz="0.0535 0.209285 0.176625"/>
    <!-- location of bottom front bolt hole location -->
    <parent link="torso_lift_link"/>
    <child link="l_torso_lift_side_plate_link"/>
  </joint>
  <link name="l_torso_lift_side_plate_link">
    <inertial>
      <mass value="0.1"/>
      <origin xyz="-0.0625 0.0 0.05"/>
      <!-- center of the 12.5cm by 10cm bolt hole pattern -->
      <inertia ixx="0.001" ixy="0.0" ixz="0.0" iyy="0.001" iyz="0.0" izz="0.001"/>
    </inertial>
  </link>
  <joint name="r_torso_lift_side_plate_joint" type="fixed">
    <origin xyz="0.0535  -0.209285 0.176625"/>
    <!-- location of bottom front bolt hole location -->
    <parent link="torso_lift_link"/>
    <child link="r_torso_lift_side_plate_link"/>
  </joint>
  <link name="r_torso_lift_side_plate_link">
    <inertial>
      <mass value="0.1"/>
      <origin xyz="-0.0625 0.0 0.05"/>
      <!-- center of the 12.5cm by 10cm bolt hole pattern -->
      <inertia ixx="0.001" ixy="0.0" ixz="0.0" iyy="0.001" iyz="0.0" izz="0.001"/>
    </inertial>
  </link>
  <!-- actuated motor screw joint -->
  <link name="torso_lift_motor_screw_link">
    <inertial>
      <mass value="1.0"/>
      <origin rpy="0 0 0" xyz="0 0 0"/>
      <inertia ixx="0.001" ixy="0.0" ixz="0.0" iyy="0.001" iyz="0.0" izz="0.001"/>
    </inertial>
    <!-- for debugging only
      <visual>
        <origin xyz="0 0 0" rpy="0 0 0" />
        <geometry>
          <box size="0.5 0.7 0.01" />
        </geometry>
      </visual>
      <collision>
        <origin xyz="0 0 0" rpy="0 0 0" />
        <geometry>
          <box size="0.5 0.7 0.01" />
        </geometry>
      </collision>
      -->
  </link>
  <joint name="torso_lift_motor_screw_joint" type="continuous">
    <origin xyz="-0.15 0.0 0.7"/>
    <axis xyz="0 0 1"/>
    <parent link="base_link"/>
    <child link="torso_lift_motor_screw_link"/>
    <dynamics damping="0.0001"/>
  </joint>
  <gazebo reference="torso_lift_link">
    <sensor name="torso_lift_contact_sensor" type="contact">
      <contact>
        <collision>torso_lift_link_collision</collision>
      </contact>
      <update_rate>100.0</update_rate>
      <plugin filename="libgazebo_ros_bumper.so" name="torso_lift_gazebo_ros_bumper_controller">
        <alwaysOn>true</alwaysOn>
        <updateRate>100.0</updateRate>
        <bumperTopicName>torso_lift_bumper</bumperTopicName>
        <frameName>world</frameName>
      </plugin>
    </sensor>
  </gazebo>
  <gazebo>
    <joint name="torso_lift_screw_torso_lift_joint" type="screw">
      <parent>torso_lift_link</parent>
      <child>torso_lift_motor_screw_link</child>
      <axis>
        <xyz>0 0 1</xyz>
      </axis>
      <thread_pitch>3141.6</thread_pitch>
    </joint>
  </gazebo>
  <transmission name="torso_lift_trans" type="pr2_mechanism_model/SimpleTransmission">
    <actuator name="torso_lift_motor"/>
    <joint name="torso_lift_joint"/>
    <mechanicalReduction>-47641.53</mechanicalReduction>
    <simulated_actuated_joint name="torso_lift_motor_screw_joint" simulated_reduction="3141.6"/>
  </transmission>
  <joint name="imu_joint" type="fixed">
    <axis xyz="0 1 0"/>
    <origin rpy="0 3.14159265359 0" xyz="-0.02977 -0.1497 0.164"/>
    <parent link="torso_lift_link"/>
    <child link="imu_link"/>
  </joint>
  <link name="imu_link">
    <inertial>
      <mass value="0.001"/>
      <origin rpy="0 0 0" xyz="0 0 0"/>
      <inertia ixx="0.0001" ixy="0" ixz="0" iyy="0.000001" iyz="0" izz="0.0001"/>
    </inertial>
  </link>
  <gazebo>
    <plugin filename="libgazebo_ros_imu.so" name="imu_controller">
      <alwaysOn>true</alwaysOn>
      <updateRate>100.0</updateRate>
      <bodyName>imu_link</bodyName>
      <topicName>torso_lift_imu/data</topicName>
      <gaussianNoise>2.89e-08</gaussianNoise>
      <xyzOffset>0 0 0</xyzOffset>
      <rpyOffset>0 -180.0 0</rpyOffset>
      <serviceName>/default_imu</serviceName>
    </plugin>
  </gazebo>
  <joint name="head_pan_joint" type="revolute">
    <axis xyz="0 0 1"/>
    <limit effort="2.645" lower="-3.007" upper="3.007" velocity="6"/>
    <!-- alpha tested velocity and effort limits -->
    <safety_controller k_position="100" k_velocity="1.5" soft_lower_limit="-2.857" soft_upper_limit="2.857"/>
    <calibration rising="0.0"/>
    <dynamics damping="0.5"/>
    <origin rpy="0.0 0.0 0.0" xyz="0.0    0.0     0.3915"/>
    <parent link="torso_lift_link"/>
    <child link="head_pan_link"/>
  </joint>
  <link name="head_pan_link">
    <inertial>
      <mass value="6.339"/>
      <!-- mass/cog/moi updated per 100505_link_data.xls -->
      <origin rpy="0 0 0" xyz="0.010907 0.031693 0.090507"/>
      <inertia ixx="0.032497592" ixy="0.00063604088" ixz="0.0025851534" iyy="0.046545627" iyz="-0.0024534295" izz="0.057652724"/>
    </inertial>
    <visual>
      <origin rpy="0 0 0 " xyz="0 0 0.0"/>
      <geometry>
        <mesh filename="/pr2_description/meshes/head_v0/head_pan.fbx"/>
      </geometry>
      <material name="Blue"/>
    </visual>
    <collision>
      <geometry>
        <mesh filename="/pr2_description/meshes/head_v0/head_pan_L.fbx"/>
      </geometry>
    </collision>
  </link>
  <transmission name="head_pan_trans" type="pr2_mechanism_model/SimpleTransmission">
    <actuator name="head_pan_motor"/>
    <joint name="head_pan_joint"/>
    <mechanicalReduction>6.0</mechanicalReduction>
  </transmission>
  <joint name="head_tilt_joint" type="revolute">
    <axis xyz="0 1 0"/>
    <limit effort="18" lower="-0.471238" upper="1.39626" velocity="5"/>
    <!-- alpha tested velocity and effort limits -->
    <safety_controller k_position="100" k_velocity="3.0" soft_lower_limit="-0.3712" soft_upper_limit="1.29626"/>
    <calibration falling="0.0"/>
    <dynamics damping="10.0"/>
    <origin rpy="0 0 0" xyz="0.068 0 0"/>
    <parent link="head_pan_link"/>
    <child link="head_tilt_link"/>
  </joint>
  <link name="head_tilt_link">
    <inertial>
      <mass value="4.479"/>
      <!-- mass/cog/moi updated per 100505_link_data.xls -->
      <origin rpy="0 0 0" xyz="0.001716 -0.019556 0.055002"/>
      <inertia ixx="0.024223222" ixy="0.00062063507" ixz="-0.000096909696" iyy="0.054723086" iyz="0.00279702400" izz="0.067306377"/>
    </inertial>
    <visual>
      <origin rpy="0.0 0.0 0.0" xyz="0 0 0"/>
      <geometry>
        <mesh filename="/pr2_description/meshes/head_v0/head_tilt.fbx"/>
      </geometry>
      <material name="Green"/>
    </visual>
    <collision>
      <origin rpy="0.0 0.0 0.0" xyz="0 0 0"/>
      <geometry>
        <mesh filename="/pr2_description/meshes/head_v0/head_tilt_L.fbx"/>
      </geometry>
    </collision>
  </link>
  <transmission name="head_tilt_trans" type="pr2_mechanism_model/SimpleTransmission">
    <actuator name="head_tilt_motor"/>
    <joint name="head_tilt_joint"/>
    <mechanicalReduction>6.0</mechanicalReduction>
  </transmission>
  <!-- Head plate frame -->
  <joint name="head_plate_frame_joint" type="fixed">
    <origin rpy="0 0 0" xyz="0.0232 0 0.0645"/>
    <parent link="head_tilt_link"/>
    <child link="head_plate_frame"/>
  </joint>
  <link name="head_plate_frame">
    <inertial>
      <mass value="0.01"/>
      <origin rpy="0 0 0" xyz="0 0 0"/>
      <inertia ixx="0.001" ixy="0.0" ixz="0.0" iyy="0.001" iyz="0.0" izz="0.001"/>
    </inertial>
    <visual>
      <origin rpy="0 0 0" xyz="0 0 0"/>
      <geometry>
        <box size="0.01 0.01 0.01"/>
      </geometry>
      <material name="Blue"/>
    </visual>
    <collision>
      <origin rpy="0 0 0" xyz="0 0 0"/>
      <geometry>
        <box size="0.01 0.01 0.01"/>
      </geometry>
    </collision>
  </link>
  <gazebo reference="head_plate_frame">
    <material value="Gazebo/Grey"/>
  </gazebo>
  <joint name="projector_wg6802418_frame_joint" type="fixed">
    <origin rpy="0 0 0" xyz="0 0.109 0.035"/>
    <parent link="head_plate_frame"/>
    <child link="projector_wg6802418_frame"/>
  </joint>
  <link name="projector_wg6802418_frame">
    <inertial>
      <mass value="0.01"/>
      <origin rpy="0 0 0" xyz="0 0 0"/>
      <inertia ixx="0.001" ixy="0.0" ixz="0.0" iyy="0.001" iyz="0.0" izz="0.001"/>
    </inertial>
  </link>
  <joint name="projector_wg6802418_child_frame_joint" type="fixed">
    <origin rpy="0 -1.57079632679 0" xyz="0 0 0"/>
    <parent link="projector_wg6802418_frame"/>
    <child link="projector_wg6802418_child_frame"/>
  </joint>
  <link name="projector_wg6802418_child_frame">
    <inertial>
      <mass value="0.01"/>
      <origin rpy="0 0 0" xyz="0 0 0"/>
      <inertia ixx="0.001" ixy="0.0" ixz="0.0" iyy="0.001" iyz="0.0" izz="0.001"/>
    </inertial>
  </link>
  <gazebo reference="projector_wg6802418_child_frame">
    <projector name="projector_wg6802418_projector_wg6802418">
      <pose>0 0 0 0 -1.5707 0</pose>
      <texture>stereo_projection_pattern_high_res_red.png</texture>
      <fov>0.959931088597</fov>
      <near_clip>0.1</near_clip>
      <far_clip>10</far_clip>
    </projector>
  </gazebo>
  <gazebo>
    <plugin filename="libgazebo_ros_projector.so" name="projector_wg6802418_controller">
      <projector>projector_wg6802418_child_frame/projector_wg6802418_projector_wg6802418</projector>
      <alwaysOn>true</alwaysOn>
      <updateRate>15.0</updateRate>
      <textureName>stereo_projection_pattern_high_res_red.png</textureName>
      <filterTextureName>stereo_projection_pattern_filter.png</filterTextureName>
      <textureTopicName>projector_wg6802418_controller/image</textureTopicName>
      <projectorTopicName>projector_wg6802418_controller/projector</projectorTopicName>
    </plugin>
  </gazebo>
  <joint name="sensor_mount_frame_joint" type="fixed">
    <origin rpy="0 0 0" xyz="0.0 0.0 0.0"/>
    <parent link="head_plate_frame"/>
    <child link="sensor_mount_link"/>
  </joint>
  <link name="sensor_mount_link">
    <inertial>
      <!-- Needs verification with CAD -->
      <mass value="0.05"/>
      <origin rpy="0 0 0" xyz="0 0 0"/>
      <inertia ixx="0.001" ixy="0.0" ixz="0.0" iyy="0.001" iyz="0.0" izz="0.01"/>
    </inertial>
    <!-- Should probably get real visuals here at some point -->
    <visual>
      <origin rpy="0 0 0" xyz="0 0 0"/>
      <geometry>
        <box size="0.01 0.01 0.01"/>
      </geometry>
      <material name="Blue"/>
    </visual>
  </link>
  <joint name="high_def_frame_joint" type="fixed">
    <origin rpy="0 0 0" xyz="0.046457 -0.110 0.054600"/>
    <parent link="sensor_mount_link"/>
    <child link="high_def_frame"/>
  </joint>
  <link name="high_def_frame">
    <inertial>
      <mass value="0.01"/>
      <origin rpy="0 0 0" xyz="0 0 0"/>
      <inertia ixx="0.001" ixy="0.0" ixz="0.0" iyy="0.001" iyz="0.0" izz="0.001"/>
    </inertial>
  </link>
  <joint name="high_def_optical_frame_joint" type="fixed">
    <origin rpy="-1.57079632679 0.0 -1.57079632679" xyz="0.0            0.0         0.0"/>
    <parent link="high_def_frame"/>
    <child link="high_def_optical_frame"/>
  </joint>
  <link name="high_def_optical_frame">
    <inertial>
      <mass value="0.01"/>
      <origin rpy="0 0 0" xyz="0 0 0"/>
      <inertia ixx="0.001" ixy="0.0" ixz="0.0" iyy="0.001" iyz="0.0" izz="0.001"/>
    </inertial>
  </link>
  <gazebo reference="high_def_frame">
    <sensor name="high_def_sensor" type="camera">
      <always_on>true</always_on>
      <update_rate>20.0</update_rate>
      <camera>
        <horizontal_fov>0.785398163397</horizontal_fov>
        <image>
          <format>R8G8B8</format>
          <width>2448</width>
          <height>2050</height>
        </image>
        <clip>
          <near>0.1</near>
          <far>100</far>
        </clip>
      </camera>
      <plugin filename="libgazebo_ros_prosilica.so" name="high_def_controller">
        <updateRate>20.0</updateRate>
        <cameraName>prosilica</cameraName>
        <imageTopicName>image_raw</imageTopicName>
        <cameraInfoTopicName>camera_info</cameraInfoTopicName>
        <pollServiceName>request_image</pollServiceName>
        <frameName>high_def_optical_frame</frameName>
        <CxPrime>1224.5</CxPrime>
        <Cx>1224.5</Cx>
        <Cy>1025.5</Cy>
        <focalLength>2954.998083</focalLength>
        <distortionK1>0.0</distortionK1>
        <distortionK2>0.0</distortionK2>
        <distortionK3>0.0</distortionK3>
        <distortionT1>0.0</distortionT1>
        <distortionT2>0.0</distortionT2>
      </plugin>
    </sensor>
    <material value="Gazebo/Black"/>
  </gazebo>
  <!-- Define link to stereo cameras, set origin relative to that -->
  <joint name="double_stereo_frame_joint" type="fixed">
    <origin rpy="0 0 0" xyz="0.0 0.0 0.0"/>
    <parent link="sensor_mount_link"/>
    <child link="double_stereo_link"/>
  </joint>
  <link name="double_stereo_link">
    <inertial>
      <!-- Needs verification with CAD -->
      <mass value="0.1"/>
      <origin rpy="0 0 0" xyz="0 0 0"/>
      <inertia ixx="0.001" ixy="0.0" ixz="0.0" iyy="0.001" iyz="0.0" izz="0.01"/>
    </inertial>
    <!-- Should probably get real visuals here at some point -->
    <visual>
      <origin rpy="0 0 0" xyz="-0.01 0 0.025"/>
      <geometry>
        <box size="0.02 0.12 0.05"/>
      </geometry>
      <material name="Blue"/>
    </visual>
  </link>
  <joint name="wide_stereo_frame_joint" type="fixed">
    <origin rpy="0.0   0.0   0.0" xyz="0.045 0.03 0.0501"/>
    <parent link="double_stereo_link"/>
    <child link="wide_stereo_link"/>
  </joint>
  <!-- camera link is at center of the optical frame, but in x-forward notation -->
  <link name="wide_stereo_link">
    <inertial>
      <mass value="0.1"/>
      <origin rpy="0 0 0" xyz="0 0 0"/>
      <inertia ixx="0.01" ixy="0" ixz="0" iyy="0.01" iyz="0" izz="0.01"/>
      <!-- this inertia is made up for now. -->
    </inertial>
  </link>
  <!-- attach optical frame to the camera link -->
  <joint name="wide_stereo_optical_frame_joint" type="fixed">
    <origin rpy="-1.57079632679 0.0 -1.57079632679" xyz="0 0 0"/>
    <!-- rotate frame from x-forward to z-forward camera coords -->
    <parent link="wide_stereo_link"/>
    <child link="wide_stereo_optical_frame"/>
  </joint>
  <!-- optical frame for the stereo camera, with z-forward notation, this is the frame stereo camera images users should refer to -->
  <link name="wide_stereo_optical_frame" type="camera"/>
  <joint name="wide_stereo_l_stereo_camera_frame_joint" type="fixed">
    <origin rpy="0 0 0" xyz="0 0 0"/>
    <parent link="wide_stereo_link"/>
    <child link="wide_stereo_l_stereo_camera_frame"/>
  </joint>
  <link name="wide_stereo_l_stereo_camera_frame">
    <inertial>
      <mass value="0.01"/>
      <origin xyz="0 0 0"/>
      <inertia ixx="0.001" ixy="0.0" ixz="0.0" iyy="0.001" iyz="0.0" izz="0.001"/>
    </inertial>
  </link>
  <joint name="wide_stereo_l_stereo_camera_optical_frame_joint" type="fixed">
    <origin rpy="-1.57079632679 0.0 -1.57079632679" xyz="0 0 0"/>
    <parent link="wide_stereo_l_stereo_camera_frame"/>
    <child link="wide_stereo_l_stereo_camera_optical_frame"/>
  </joint>
  <link name="wide_stereo_l_stereo_camera_optical_frame"/>
  <gazebo reference="wide_stereo_l_stereo_camera_frame">
    <sensor name="wide_stereo_l_stereo_camera_sensor" type="camera">
      <always_on>true</always_on>
      <update_rate>25.0</update_rate>
      <camera>
        <horizontal_fov>1.57079632679</horizontal_fov>
        <image>
          <format>BAYER_BGGR8</format>
          <width>640</width>
          <height>480</height>
        </image>
        <clip>
          <near>0.1</near>
          <far>100</far>
        </clip>
      </camera>
      <plugin filename="libgazebo_ros_camera.so" name="wide_stereo_l_stereo_camera_controller">
        <alwaysOn>true</alwaysOn>
        <updateRate>25.0</updateRate>
        <cameraName>wide_stereo/left</cameraName>
        <imageTopicName>image_raw</imageTopicName>
        <cameraInfoTopicName>camera_info</cameraInfoTopicName>
        <frameName>wide_stereo_optical_frame</frameName>
        <hackBaseline>0</hackBaseline>
        <CxPrime>320.5</CxPrime>
        <Cx>320.5</Cx>
        <Cy>240.5</Cy>
        <!-- image_width / (2*tan(hfov_radian /2)) -->
        <!-- 320 for wide and 772.55 for narrow stereo camera -->
        <focalLength>320.000105</focalLength>
        <distortionK1>0.0</distortionK1>
        <distortionK2>0.0</distortionK2>
        <distortionK3>0.0</distortionK3>
        <distortionT1>0.0</distortionT1>
        <distortionT2>0.0</distortionT2>
      </plugin>
    </sensor>
    <turnGravityOff>true</turnGravityOff>
    <material>PR2/Blue</material>
  </gazebo>
  <joint name="wide_stereo_r_stereo_camera_frame_joint" type="fixed">
    <origin rpy="0.0 0.0 0.0" xyz="0.0 -0.09 0.0"/>
    <parent link="wide_stereo_l_stereo_camera_frame"/>
    <child link="wide_stereo_r_stereo_camera_frame"/>
  </joint>
  <link name="wide_stereo_r_stereo_camera_frame">
    <inertial>
      <mass value="0.01"/>
      <origin xyz="0 0 0"/>
      <inertia ixx="0.001" ixy="0.0" ixz="0.0" iyy="0.001" iyz="0.0" izz="0.001"/>
    </inertial>
  </link>
  <joint name="wide_stereo_r_stereo_camera_optical_frame_joint" type="fixed">
    <origin rpy="-1.57079632679 0.0 -1.57079632679" xyz="0 0 0"/>
    <parent link="wide_stereo_r_stereo_camera_frame"/>
    <child link="wide_stereo_r_stereo_camera_optical_frame"/>
  </joint>
  <link name="wide_stereo_r_stereo_camera_optical_frame"/>
  <gazebo reference="wide_stereo_r_stereo_camera_frame">
    <sensor name="wide_stereo_r_stereo_camera_sensor" type="camera">
      <always_on>true</always_on>
      <update_rate>25.0</update_rate>
      <camera>
        <horizontal_fov>1.57079632679</horizontal_fov>
        <image>
          <format>BAYER_BGGR8</format>
          <width>640</width>
          <height>480</height>
        </image>
        <clip>
          <near>0.1</near>
          <far>100</far>
        </clip>
      </camera>
      <plugin filename="libgazebo_ros_camera.so" name="wide_stereo_r_stereo_camera_controller">
        <alwaysOn>true</alwaysOn>
        <updateRate>25.0</updateRate>
        <cameraName>wide_stereo/right</cameraName>
        <imageTopicName>image_raw</imageTopicName>
        <cameraInfoTopicName>camera_info</cameraInfoTopicName>
        <frameName>wide_stereo_optical_frame</frameName>
        <hackBaseline>0.09</hackBaseline>
        <CxPrime>320.5</CxPrime>
        <Cx>320.5</Cx>
        <Cy>240.5</Cy>
        <!-- image_width / (2*tan(hfov_radian /2)) -->
        <!-- 320 for wide and 772.55 for narrow stereo camera -->
        <focalLength>320.000105</focalLength>
        <distortionK1>0.0</distortionK1>
        <distortionK2>0.0</distortionK2>
        <distortionK3>0.0</distortionK3>
        <distortionT1>0.0</distortionT1>
        <distortionT2>0.0</distortionT2>
      </plugin>
    </sensor>
    <turnGravityOff>true</turnGravityOff>
    <material>PR2/Blue</material>
  </gazebo>
  <gazebo reference="wide_stereo_link">
    <material value="PR2/Blue"/>
    <turnGravityOff value="true"/>
  </gazebo>
  <gazebo reference="wide_stereo_optical_frame">
    <material value="Gazebo/White"/>
    <turnGravityOff value="true"/>
  </gazebo>
  <joint name="narrow_stereo_frame_joint" type="fixed">
    <origin rpy="0.0   0.0   0.0" xyz="0.045 0.06 0.0501"/>
    <parent link="double_stereo_link"/>
    <child link="narrow_stereo_link"/>
  </joint>
  <!-- camera link is at center of the optical frame, but in x-forward notation -->
  <link name="narrow_stereo_link">
    <inertial>
      <mass value="0.1"/>
      <origin rpy="0 0 0" xyz="0 0 0"/>
      <inertia ixx="0.01" ixy="0" ixz="0" iyy="0.01" iyz="0" izz="0.01"/>
      <!-- this inertia is made up for now. -->
    </inertial>
  </link>
  <!-- attach optical frame to the camera link -->
  <joint name="narrow_stereo_optical_frame_joint" type="fixed">
    <origin rpy="-1.57079632679 0.0 -1.57079632679" xyz="0 0 0"/>
    <!-- rotate frame from x-forward to z-forward camera coords -->
    <parent link="narrow_stereo_link"/>
    <child link="narrow_stereo_optical_frame"/>
  </joint>
  <!-- optical frame for the stereo camera, with z-forward notation, this is the frame stereo camera images users should refer to -->
  <link name="narrow_stereo_optical_frame" type="camera"/>
  <joint name="narrow_stereo_l_stereo_camera_frame_joint" type="fixed">
    <origin rpy="0 0 0" xyz="0 0 0"/>
    <parent link="narrow_stereo_link"/>
    <child link="narrow_stereo_l_stereo_camera_frame"/>
  </joint>
  <link name="narrow_stereo_l_stereo_camera_frame">
    <inertial>
      <mass value="0.01"/>
      <origin xyz="0 0 0"/>
      <inertia ixx="0.001" ixy="0.0" ixz="0.0" iyy="0.001" iyz="0.0" izz="0.001"/>
    </inertial>
  </link>
  <joint name="narrow_stereo_l_stereo_camera_optical_frame_joint" type="fixed">
    <origin rpy="-1.57079632679 0.0 -1.57079632679" xyz="0 0 0"/>
    <parent link="narrow_stereo_l_stereo_camera_frame"/>
    <child link="narrow_stereo_l_stereo_camera_optical_frame"/>
  </joint>
  <link name="narrow_stereo_l_stereo_camera_optical_frame"/>
  <gazebo reference="narrow_stereo_l_stereo_camera_frame">
    <sensor name="narrow_stereo_l_stereo_camera_sensor" type="camera">
      <always_on>true</always_on>
      <update_rate>25.0</update_rate>
      <camera>
        <horizontal_fov>0.785398163397</horizontal_fov>
        <image>
          <format>L8</format>
          <width>640</width>
          <height>480</height>
        </image>
        <clip>
          <near>0.1</near>
          <far>100</far>
        </clip>
      </camera>
      <plugin filename="libgazebo_ros_camera.so" name="narrow_stereo_l_stereo_camera_controller">
        <alwaysOn>true</alwaysOn>
        <updateRate>25.0</updateRate>
        <cameraName>narrow_stereo/left</cameraName>
        <imageTopicName>image_raw</imageTopicName>
        <cameraInfoTopicName>camera_info</cameraInfoTopicName>
        <frameName>narrow_stereo_optical_frame</frameName>
        <hackBaseline>0</hackBaseline>
        <CxPrime>320.5</CxPrime>
        <Cx>320.5</Cx>
        <Cy>240.5</Cy>
        <!-- image_width / (2*tan(hfov_radian /2)) -->
        <!-- 320 for wide and 772.55 for narrow stereo camera -->
        <focalLength>772.548518</focalLength>
        <distortionK1>0.0</distortionK1>
        <distortionK2>0.0</distortionK2>
        <distortionK3>0.0</distortionK3>
        <distortionT1>0.0</distortionT1>
        <distortionT2>0.0</distortionT2>
      </plugin>
    </sensor>
    <turnGravityOff>true</turnGravityOff>
    <material>PR2/Blue</material>
  </gazebo>
  <joint name="narrow_stereo_r_stereo_camera_frame_joint" type="fixed">
    <origin rpy="0.0 0.0 0.0" xyz="0.0 -0.09 0.0"/>
    <parent link="narrow_stereo_l_stereo_camera_frame"/>
    <child link="narrow_stereo_r_stereo_camera_frame"/>
  </joint>
  <link name="narrow_stereo_r_stereo_camera_frame">
    <inertial>
      <mass value="0.01"/>
      <origin xyz="0 0 0"/>
      <inertia ixx="0.001" ixy="0.0" ixz="0.0" iyy="0.001" iyz="0.0" izz="0.001"/>
    </inertial>
  </link>
  <joint name="narrow_stereo_r_stereo_camera_optical_frame_joint" type="fixed">
    <origin rpy="-1.57079632679 0.0 -1.57079632679" xyz="0 0 0"/>
    <parent link="narrow_stereo_r_stereo_camera_frame"/>
    <child link="narrow_stereo_r_stereo_camera_optical_frame"/>
  </joint>
  <link name="narrow_stereo_r_stereo_camera_optical_frame"/>
  <gazebo reference="narrow_stereo_r_stereo_camera_frame">
    <sensor name="narrow_stereo_r_stereo_camera_sensor" type="camera">
      <always_on>true</always_on>
      <update_rate>25.0</update_rate>
      <camera>
        <horizontal_fov>0.785398163397</horizontal_fov>
        <image>
          <format>L8</format>
          <width>640</width>
          <height>480</height>
        </image>
        <clip>
          <near>0.1</near>
          <far>100</far>
        </clip>
      </camera>
      <plugin filename="libgazebo_ros_camera.so" name="narrow_stereo_r_stereo_camera_controller">
        <alwaysOn>true</alwaysOn>
        <updateRate>25.0</updateRate>
        <cameraName>narrow_stereo/right</cameraName>
        <imageTopicName>image_raw</imageTopicName>
        <cameraInfoTopicName>camera_info</cameraInfoTopicName>
        <frameName>narrow_stereo_optical_frame</frameName>
        <hackBaseline>0.09</hackBaseline>
        <CxPrime>320.5</CxPrime>
        <Cx>320.5</Cx>
        <Cy>240.5</Cy>
        <!-- image_width / (2*tan(hfov_radian /2)) -->
        <!-- 320 for wide and 772.55 for narrow stereo camera -->
        <focalLength>772.548518</focalLength>
        <distortionK1>0.0</distortionK1>
        <distortionK2>0.0</distortionK2>
        <distortionK3>0.0</distortionK3>
        <distortionT1>0.0</distortionT1>
        <distortionT2>0.0</distortionT2>
      </plugin>
    </sensor>
    <turnGravityOff>true</turnGravityOff>
    <material>PR2/Blue</material>
  </gazebo>
  <gazebo reference="narrow_stereo_link">
    <material value="PR2/Blue"/>
    <turnGravityOff value="true"/>
  </gazebo>
  <gazebo reference="narrow_stereo_optical_frame">
    <material value="Gazebo/White"/>
    <turnGravityOff value="true"/>
  </gazebo>
  <!-- Define link to stereo cameras, set origin relative to that -->
  <gazebo reference="double_stereo_double_stereo_link">
    <material value="PR2/Blue"/>
  </gazebo>
  <gazebo reference="sensor_mount_sensor_link">
    <material value="PR2/Blue"/>
  </gazebo>
  <joint name="laser_tilt_mount_joint" type="revolute">
    <axis xyz="0 1 0"/>
    <limit effort="0.65" lower="-0.7854" upper="1.48353" velocity="10.0"/>
    <!-- alpha tested velocity and effort limits -->
    <safety_controller k_position="100" k_velocity="0.05" soft_lower_limit="-0.7354" soft_upper_limit="1.43353"/>
    <calibration falling="0.0"/>
    <dynamics damping="0.008"/>
    <origin rpy="0 0 0" xyz="0.1 0 0.235"/>
    <parent link="torso_lift_link"/>
    <child link="laser_tilt_mount_link"/>
  </joint>
  <link name="laser_tilt_mount_link">
    <inertial>
      <mass value="0.591"/>
      <origin rpy="0 0 0" xyz="-0.001136 0.00167 -0.00713"/>
      <inertia ixx="0.001195273" ixy="0.000023087" ixz="0.000037467" iyy="0.001083956" iyz="0.000034906" izz="0.000795014"/>
    </inertial>
    <visual>
      <origin rpy="0 0 0" xyz="0 0 0"/>
      <geometry>
        <mesh filename="/pr2_description/meshes/tilting_laser_v0/tilting_hokuyo.fbx"/>
      </geometry>
      <material name="Red"/>
    </visual>
    <collision>
      <origin rpy="0 0 0" xyz="0 0 0"/>
      <geometry>
        <mesh filename="/pr2_description/meshes/tilting_laser_v0/tilting_hokuyo_L.fbx"/>
      </geometry>
    </collision>
  </link>
  <joint name="laser_tilt_joint" type="fixed">
    <axis xyz="0 1 0"/>
    <origin rpy="0 0 0" xyz="0 0 0.03"/>
    <parent link="laser_tilt_mount_link"/>
    <child link="laser_tilt_link"/>
  </joint>
  <link name="laser_tilt_link" type="laser">
    <inertial>
      <mass value="0.001"/>
      <origin rpy="0 0 0" xyz="0 0 0"/>
      <inertia ixx="0.0001" ixy="0" ixz="0" iyy="0.000001" iyz="0" izz="0.0001"/>
    </inertial>
  </link>
  <gazebo reference="laser_tilt_link">
    <sensor name="laser_tilt" type="ray">
      <always_on>true</always_on>
      <update_rate>40</update_rate>
      <pose>0 0 0 0 0 0</pose>
      <visualize>false</visualize>
      <ray>
        <scan>
          <horizontal>
            <samples>640</samples>
            <resolution>1</resolution>
            <min_angle>-1.3962634</min_angle>
            <max_angle>1.3962634</max_angle>
          </horizontal>
        </scan>
        <range>
          <min>0.08</min>
          <max>10.0</max>
          <resolution>0.01</resolution>
        </range>
      </ray>
      <plugin filename="libgazebo_ros_laser.so" name="gazebo_ros_laser_tilt_controller">
        <gaussianNoise>0.005</gaussianNoise>
        <alwaysOn>true</alwaysOn>
        <updateRate>40</updateRate>
        <topicName>tilt_scan</topicName>
        <frameName>laser_tilt_link</frameName>
        <hokuyoMinIntensity>101</hokuyoMinIntensity>
      </plugin>
    </sensor>
  </gazebo>
  <gazebo reference="laser_tilt_mount_link">
    </gazebo>
  <transmission name="laser_tilt_mount_trans" type="pr2_mechanism_model/SimpleTransmission">
    <actuator name="laser_tilt_mount_motor"/>
    <joint name="laser_tilt_mount_joint"/>
    <mechanicalReduction>-6.05</mechanicalReduction>
  </transmission>
</robot>
