<?xml version="1.0" ?>
<!-- =================================================================================== -->
<!-- |    This document was autogenerated by xacro from pr2_no_arms.urdf.xacro         | -->
<!-- |    EDITING THIS FILE BY HAND IS NOT RECOMMENDED                                 | -->
<!-- =================================================================================== -->
<robot name="pr2" xmlns:controller="http://playerstage.sourceforge.net/gazebo/xmlschema/#controller" xmlns:interface="http://playerstage.sourceforge.net/gazebo/xmlschema/#interface" xmlns:sensor="http://playerstage.sourceforge.net/gazebo/xmlschema/#sensor" xmlns:xacro="http://playerstage.sourceforge.net/gazebo/xmlschema/#interface">
  <!-- DATA SOURCES -->
  <!-- all link offsets, CG, limits are obtained from Function Engineering spreadsheet 090224_link_data.xls unless stated otherwise -->
  <!-- all link geometry sizes are obtained from Function provided CAD model unless stated otherwise -->
  <!-- all simplified collision geometry are hand approximated from CAD model, sometimes from respective bounding boxes -->
  <!-- This is the 'effective' wheel radius. Wheel radius for uncompressed wheel is 0.079.  mp 20080801 -->
  <!-- Now we can start using the macros included above to define the actual PR2 -->
  <link name="base_link">
    <inertial>
      <mass value="116.0"/>
      <origin xyz="-0.061 0.0 0.1465"/>
      <inertia ixx="5.652232699207" ixy="-0.009719934438" ixz="1.293988226423" iyy="5.669473158652" iyz="-0.007379583694" izz="3.683196351726"/>
    </inertial>
    <visual>
      <origin rpy="0 0 0" xyz="0 0 0"/>
      <geometry>
        <mesh filename="/pr2_description/meshes/base_v0/base.fbx"/>
      </geometry>
    </visual>
  </link>
  <!-- base_footprint is a fictitious link(frame) that is on the ground right below base_link origin,
         navigation stack dedpends on this frame -->
  <link name="base_footprint">
    <inertial>
      <mass value="1.0"/>
      <origin xyz="0 0 0"/>
      <inertia ixx="0.01" ixy="0.0" ixz="0.0" iyy="0.01" iyz="0.0" izz="0.01"/>
    </inertial>
    <visual>
      <origin rpy="0 0 0" xyz="0 0 0"/>
      <geometry>
        <box size="0.01 0.01 0.01"/>
      </geometry>
    </visual>
  </link>
  <joint name="base_footprint_joint" type="fixed">
    <origin rpy="0 0 0" xyz="0 0 0.051"/>
    <child link="base_link"/>
    <parent link="base_footprint"/>
  </joint>
  <!-- visualize bellow -->
  <link name="base_bellow_link">
    <inertial>
      <mass value="1.0"/>
      <origin xyz="0 0 0"/>
      <inertia ixx="0.01" ixy="0.0" ixz="0.0" iyy="0.01" iyz="0.0" izz="0.01"/>
    </inertial>
    <visual>
      <origin rpy="0 0 0" xyz="0 0 0"/>
      <geometry>
        <box size="0.05 0.37 0.3"/>
      </geometry>
    </visual>
  </link>
  <joint name="base_bellow_joint" type="fixed">
    <origin rpy="0 0 0" xyz="-0.29 0 0.8"/>
    <parent link="base_link"/>
    <child link="base_bellow_link"/>
  </joint>
   
  <joint name="fl_caster_rotation_joint" type="continuous">
    <axis xyz="0 0 1"/>
    <limit effort="6.5" velocity="10"/>
    <!-- alpha tested velocity and effort limits -->
    <origin rpy="0 0 0" xyz="0.2246 0.2246 0.0282"/>
    <parent link="base_link"/>
    <child link="fl_caster_rotation_link"/>
  </joint>
  <link name="fl_caster_rotation_link">
    <inertial>
      <mass value="3.473082"/>
      <origin xyz="0 0 0.07"/>
      <inertia ixx="0.012411765597" ixy="-0.000711733678" ixz="0.00050272983" iyy="0.015218160428" iyz="-0.000004273467" izz="0.011763977943"/>
    </inertial>
    <visual>
      <origin rpy="0 0 0" xyz="0 0 0"/>
      <geometry>
        <mesh filename="/pr2_description/meshes/base_v0/caster.fbx"/>
      </geometry>
    </visual>
  </link>
  
  <joint name="fl_caster_l_wheel_joint" type="continuous">
    <axis xyz="0 1 0"/>
    <limit effort="7" velocity="15"/>
    <!-- alpha tested effort and velocity limits -->
    <origin rpy="0 0 0" xyz="0 .049 0"/>
    <parent link="fl_caster_rotation_link"/>
    <child link="fl_caster_l_wheel_link"/>
  </joint>
  <link name="fl_caster_l_wheel_link">
    <inertial>
      <mass value="0.44036"/>
      <origin xyz="0 0 0"/>
      <inertia ixx="0.012411765597" ixy="-0.000711733678" ixz="0.00050272983" iyy="0.015218160428" iyz="-0.000004273467" izz="0.011763977943"/>
    </inertial>
    <visual>
      <origin rpy="0 0 0" xyz="0 0 0"/>
      <geometry>
        <mesh filename="/pr2_description/meshes/base_v0/wheel.fbx"/>
      </geometry>
    </visual>
  </link>
  
   <joint name="fl_caster_r_wheel_joint" type="continuous">
    <axis xyz="0 1 0"/>
    <limit effort="7" velocity="15"/>
    <!-- alpha tested effort and velocity limits -->
    <safety_controller k_velocity="10"/>
    <dynamics damping="1.0" friction="0.0"/>
    <origin rpy="0 0 0" xyz="0 -0.049 0"/>
    <parent link="fl_caster_rotation_link"/>
    <child link="fl_caster_r_wheel_link"/>
  </joint>
  <link name="fl_caster_r_wheel_link">
    <inertial>
      <mass value="0.44036"/>
      <origin xyz="0 0 0"/>
      <inertia ixx="0.012411765597" ixy="-0.000711733678" ixz="0.00050272983" iyy="0.015218160428" iyz="-0.000004273467" izz="0.011763977943"/>
    </inertial>
    <visual>
      <origin rpy="0 0 0" xyz="0 0 0"/>
      <geometry>
        <mesh filename="/pr2_description/meshes/base_v0/wheel.fbx"/>
      </geometry>
      
    </visual>
  </link>
  
  <joint name="fr_caster_rotation_joint" type="continuous">
    <axis xyz="0 0 1"/>
    <limit effort="6.5" velocity="10"/>
    <!-- alpha tested velocity and effort limits -->
    <origin rpy="0 0 0" xyz="0.2246 -0.2246 0.0282"/>
    <parent link="base_link"/>
    <child link="fr_caster_rotation_link"/>
  </joint>
  <link name="fr_caster_rotation_link">
    <visual>
      <origin rpy="0 0 0" xyz="0 0 0"/>
      <geometry>
        <mesh filename="/pr2_description/meshes/base_v0/caster.fbx"/>
      </geometry>
    </visual>
  </link>
  
  <joint name="fr_caster_l_wheel_joint" type="continuous">
    <axis xyz="0 1 0"/>
    <limit effort="7" velocity="15"/>
    <!-- alpha tested effort and velocity limits -->
    <origin rpy="0 0 0" xyz="0 0.049 0"/>
    <parent link="fr_caster_rotation_link"/>
    <child link="fr_caster_l_wheel_link"/>
  </joint>
  <link name="fr_caster_l_wheel_link">
    <visual>
      <origin rpy="0 0 0" xyz="0 0 0"/>
      <geometry>
        <mesh filename="/pr2_description/meshes/base_v0/wheel.fbx"/>
      </geometry>
    </visual>
  </link>
  <joint name="fr_caster_r_wheel_joint" type="continuous">
    <axis xyz="0 1 0"/>
    <limit effort="7" velocity="15"/>
    <!-- alpha tested effort and velocity limits -->
    <origin rpy="0 0 0" xyz="0 -0.049 0"/>
    <parent link="fr_caster_rotation_link"/>
    <child link="fr_caster_r_wheel_link"/>
  </joint>
  <link name="fr_caster_r_wheel_link">
    <visual>
      <origin rpy="0 0 0" xyz="0 0 0"/>
      <geometry>
        <mesh filename="/pr2_description/meshes/base_v0/wheel.fbx"/>
      </geometry>
    </visual>
  </link>
  <joint name="bl_caster_rotation_joint" type="continuous">
    <axis xyz="0 0 1"/>
    <limit effort="6.5" velocity="10"/>
    <!-- alpha tested velocity and effort limits -->
    <origin rpy="0 0 0" xyz="-0.2246 0.2246 0.0282"/>
    <parent link="base_link"/>
    <child link="bl_caster_rotation_link"/>
  </joint>
  <link name="bl_caster_rotation_link">
    <visual>
      <origin rpy="0 0 0" xyz="0 0 0"/>
      <geometry>
        <mesh filename="/pr2_description/meshes/base_v0/caster.fbx"/>
      </geometry>
    </visual>
  </link>
  <joint name="bl_caster_l_wheel_joint" type="continuous">
    <axis xyz="0 1 0"/>
    <limit effort="7" velocity="15"/>
    <!-- alpha tested effort and velocity limits -->
    <origin rpy="0 0 0" xyz="0 0.049 0"/>
    <parent link="bl_caster_rotation_link"/>
    <child link="bl_caster_l_wheel_link"/>
  </joint>
  <link name="bl_caster_l_wheel_link">
    <visual>
      <origin rpy="0 0 0" xyz="0 0 0"/>
      <geometry>
        <mesh filename="/pr2_description/meshes/base_v0/wheel.fbx"/>
      </geometry>
    </visual>
  </link>
  <joint name="bl_caster_r_wheel_joint" type="continuous">
    <axis xyz="0 1 0"/>
    <limit effort="7" velocity="15"/>
    <!-- alpha tested effort and velocity limits -->
    <origin rpy="0 0 0" xyz="0 -0.049 0"/>
    <parent link="bl_caster_rotation_link"/>
    <child link="bl_caster_r_wheel_link"/>
  </joint>
  <link name="bl_caster_r_wheel_link">
    <visual>
      <origin rpy="0 0 0" xyz="0 0 0"/>
      <geometry>
        <mesh filename="/pr2_description/meshes/base_v0/wheel.fbx"/>
      </geometry>
    </visual>
  </link>
  <joint name="br_caster_rotation_joint" type="continuous">
    <axis xyz="0 0 1"/>
    <limit effort="6.5" velocity="10"/>
    <!-- alpha tested velocity and effort limits -->
    <origin rpy="0 0 0" xyz="-0.2246 -0.2246 0.0282"/>
    <parent link="base_link"/>
    <child link="br_caster_rotation_link"/>
  </joint>
  <link name="br_caster_rotation_link">
    <visual>
      <origin rpy="0 0 0" xyz="0 0 0"/>
      <geometry>
        <mesh filename="/pr2_description/meshes/base_v0/caster.fbx"/>
      </geometry>
    </visual>
  </link>
  <joint name="br_caster_l_wheel_joint" type="continuous">
    <axis xyz="0 1 0"/>
    <limit effort="7" velocity="15"/>
    <!-- alpha tested effort and velocity limits -->
    <origin rpy="0 0 0" xyz="0 0.049 0"/>
    <parent link="br_caster_rotation_link"/>
    <child link="br_caster_l_wheel_link"/>
  </joint>
  <link name="br_caster_l_wheel_link">
    <visual>
      <origin rpy="0 0 0" xyz="0 0 0"/>
      <geometry>
        <mesh filename="/pr2_description/meshes/base_v0/wheel.fbx"/>
      </geometry>
    </visual>
  </link>
  <joint name="br_caster_r_wheel_joint" type="continuous">
    <axis xyz="0 1 0"/>
    <limit effort="7" velocity="15"/>
    <!-- alpha tested effort and velocity limits -->
    <origin rpy="0 0 0" xyz="0 -0.049 0"/>
    <parent link="br_caster_rotation_link"/>
    <child link="br_caster_r_wheel_link"/>
  </joint>
  <link name="br_caster_r_wheel_link">
    <visual>
      <origin rpy="0 0 0" xyz="0 0 0"/>
      <geometry>
        <mesh filename="/pr2_description/meshes/base_v0/wheel.fbx"/>
      </geometry>
    </visual>
  </link>
  



</robot>
