<?xml version="1.0" ?>
<!-- =================================================================================== -->
<!-- |    This document was autogenerated by xacro from pr2_no_arms.urdf.xacro         | -->
<!-- |    EDITING THIS FILE BY HAND IS NOT RECOMMENDED                                 | -->
<!-- =================================================================================== -->
<robot name="pr2" xmlns:controller="http://playerstage.sourceforge.net/gazebo/xmlschema/#controller" xmlns:interface="http://playerstage.sourceforge.net/gazebo/xmlschema/#interface" xmlns:sensor="http://playerstage.sourceforge.net/gazebo/xmlschema/#sensor" xmlns:xacro="http://playerstage.sourceforge.net/gazebo/xmlschema/#interface">
  <!-- DATA SOURCES -->
  <!-- all link offsets, CG, limits are obtained from Function Engineering spreadsheet 090224_link_data.xls unless stated otherwise -->
  <!-- all link geometry sizes are obtained from Function provided CAD model unless stated otherwise -->
  <!-- all simplified collision geometry are hand approximated from CAD model, sometimes from respective bounding boxes -->
  <!-- This is the 'effective' wheel radius. Wheel radius for uncompressed wheel is 0.079.  mp 20080801 -->
  <!-- Now we can start using the macros included above to define the actual PR2 -->
  <link name="base_link">
    <visual>
      <origin rpy="0 0 0" xyz="0 0 0"/>
      <geometry>
        <mesh filename="/pr2_description/meshes/base_v0/base.fbx"/>
      </geometry>
    </visual>
  </link>
  <!-- base_footprint is a fictitious link(frame) that is on the ground right below base_link origin,
         navigation stack dedpends on this frame -->
  <link name="base_footprint">
    <visual>
      <origin rpy="0 0 0" xyz="0 0 0"/>
      <geometry>
        <box size="0.01 0.01 0.01"/>
      </geometry>
    </visual>
  </link>
  <joint name="base_footprint_joint" type="fixed">
    <origin rpy="0 0 0" xyz="0 0 0.051"/>
    <child link="base_link"/>
    <parent link="base_footprint"/>
  </joint>
  <!-- visualize bellow -->
  <link name="base_bellow_link">
    <visual>
      <origin rpy="0 0 0" xyz="0 0 0"/>
      <geometry>
        <box size="0.05 0.37 0.3"/>
      </geometry>
    </visual>
  </link>
  <joint name="base_bellow_joint" type="fixed">
    <origin rpy="0 0 0" xyz="-0.29 0 0.8"/>
    <parent link="base_link"/>
    <child link="base_bellow_link"/>
  </joint>
  <joint name="base_laser_joint" type="fixed">
    <axis xyz="0 1 0"/>
    <origin rpy="0 0 0" xyz="0.275 0.0 0.252"/>
    <parent link="base_link"/>
    <child link="base_laser_link"/>
  </joint>
  <link name="base_laser_link" type="laser">
  </link>
  <joint name="fl_caster_rotation_joint" type="continuous">
    <axis xyz="0 0 1"/>
    <limit effort="6.5" velocity="10"/>
    <!-- alpha tested velocity and effort limits -->
    <origin rpy="0 0 0" xyz="0.2246 0.2246 0.0282"/>
    <parent link="base_link"/>
    <child link="fl_caster_rotation_link"/>
  </joint>
  <link name="fl_caster_rotation_link">
    <visual>
      <origin rpy="0 0 0" xyz="0 0 0"/>
      <geometry>
        <mesh filename="/pr2_description/meshes/base_v0/caster.fbx"/>
      </geometry>
    </visual>
  </link>
  <joint name="fl_caster_l_wheel_joint" type="continuous">
    <axis xyz="0 1 0"/>
    <limit effort="7" velocity="15"/>
    <!-- alpha tested effort and velocity limits -->
    <origin rpy="0 0 0" xyz="0 0.049 0"/>
    <parent link="fl_caster_rotation_link"/>
    <child link="fl_caster_l_wheel_link"/>
  </joint>
  <link name="fl_caster_l_wheel_link">
    <visual>
      <origin rpy="0 0 0" xyz="0 0 0"/>
      <geometry>
        <mesh filename="/pr2_description/meshes/base_v0/wheel.fbx"/>
      </geometry>
    </visual>
  </link>
  <joint name="fl_caster_r_wheel_joint" type="continuous">
    <axis xyz="0 1 0"/>
    <limit effort="7" velocity="15"/>
    <!-- alpha tested effort and velocity limits -->
    <origin rpy="0 0 0" xyz="0 -0.049 0"/>
    <parent link="fl_caster_rotation_link"/>
    <child link="fl_caster_r_wheel_link"/>
  </joint>
  <link name="fl_caster_r_wheel_link">
    <visual>
      <origin rpy="0 0 0" xyz="0 0 0"/>
      <geometry>
        <mesh filename="/pr2_description/meshes/base_v0/wheel.fbx"/>
      </geometry>
    </visual>
  </link>
  <joint name="fr_caster_rotation_joint" type="continuous">
    <axis xyz="0 0 1"/>
    <limit effort="6.5" velocity="10"/>
    <!-- alpha tested velocity and effort limits -->
    <origin rpy="0 0 0" xyz="0.2246 -0.2246 0.0282"/>
    <parent link="base_link"/>
    <child link="fr_caster_rotation_link"/>
  </joint>
  <link name="fr_caster_rotation_link">
    <visual>
      <origin rpy="0 0 0" xyz="0 0 0"/>
      <geometry>
        <mesh filename="/pr2_description/meshes/base_v0/caster.fbx"/>
      </geometry>
    </visual>
  </link>
  <joint name="fr_caster_l_wheel_joint" type="continuous">
    <axis xyz="0 1 0"/>
    <limit effort="7" velocity="15"/>
    <!-- alpha tested effort and velocity limits -->
    <origin rpy="0 0 0" xyz="0 0.049 0"/>
    <parent link="fr_caster_rotation_link"/>
    <child link="fr_caster_l_wheel_link"/>
  </joint>
  <link name="fr_caster_l_wheel_link">
    <visual>
      <origin rpy="0 0 0" xyz="0 0 0"/>
      <geometry>
        <mesh filename="/pr2_description/meshes/base_v0/wheel.fbx"/>
      </geometry>
    </visual>
  </link>
  <joint name="fr_caster_r_wheel_joint" type="continuous">
    <axis xyz="0 1 0"/>
    <limit effort="7" velocity="15"/>
    <!-- alpha tested effort and velocity limits -->
    <origin rpy="0 0 0" xyz="0 -0.049 0"/>
    <parent link="fr_caster_rotation_link"/>
    <child link="fr_caster_r_wheel_link"/>
  </joint>
  <link name="fr_caster_r_wheel_link">
    <visual>
      <origin rpy="0 0 0" xyz="0 0 0"/>
      <geometry>
        <mesh filename="/pr2_description/meshes/base_v0/wheel.fbx"/>
      </geometry>
    </visual>
  </link>
  <joint name="bl_caster_rotation_joint" type="continuous">
    <axis xyz="0 0 1"/>
    <limit effort="6.5" velocity="10"/>
    <!-- alpha tested velocity and effort limits -->
    <origin rpy="0 0 0" xyz="-0.2246 0.2246 0.0282"/>
    <parent link="base_link"/>
    <child link="bl_caster_rotation_link"/>
  </joint>
  <link name="bl_caster_rotation_link">
    <visual>
      <origin rpy="0 0 0" xyz="0 0 0"/>
      <geometry>
        <mesh filename="/pr2_description/meshes/base_v0/caster.fbx"/>
      </geometry>
    </visual>
  </link>
  <joint name="bl_caster_l_wheel_joint" type="continuous">
    <axis xyz="0 1 0"/>
    <limit effort="7" velocity="15"/>
    <!-- alpha tested effort and velocity limits -->
    <origin rpy="0 0 0" xyz="0 0.049 0"/>
    <parent link="bl_caster_rotation_link"/>
    <child link="bl_caster_l_wheel_link"/>
  </joint>
  <link name="bl_caster_l_wheel_link">
    <visual>
      <origin rpy="0 0 0" xyz="0 0 0"/>
      <geometry>
        <mesh filename="/pr2_description/meshes/base_v0/wheel.fbx"/>
      </geometry>
    </visual>
  </link>
  <joint name="bl_caster_r_wheel_joint" type="continuous">
    <axis xyz="0 1 0"/>
    <limit effort="7" velocity="15"/>
    <!-- alpha tested effort and velocity limits -->
    <origin rpy="0 0 0" xyz="0 -0.049 0"/>
    <parent link="bl_caster_rotation_link"/>
    <child link="bl_caster_r_wheel_link"/>
  </joint>
  <link name="bl_caster_r_wheel_link">
    <visual>
      <origin rpy="0 0 0" xyz="0 0 0"/>
      <geometry>
        <mesh filename="/pr2_description/meshes/base_v0/wheel.fbx"/>
      </geometry>
    </visual>
  </link>
  <joint name="br_caster_rotation_joint" type="continuous">
    <axis xyz="0 0 1"/>
    <limit effort="6.5" velocity="10"/>
    <!-- alpha tested velocity and effort limits -->
    <origin rpy="0 0 0" xyz="-0.2246 -0.2246 0.0282"/>
    <parent link="base_link"/>
    <child link="br_caster_rotation_link"/>
  </joint>
  <link name="br_caster_rotation_link">
    <visual>
      <origin rpy="0 0 0" xyz="0 0 0"/>
      <geometry>
        <mesh filename="/pr2_description/meshes/base_v0/caster.fbx"/>
      </geometry>
    </visual>
  </link>
  <joint name="br_caster_l_wheel_joint" type="continuous">
    <axis xyz="0 1 0"/>
    <limit effort="7" velocity="15"/>
    <!-- alpha tested effort and velocity limits -->
    <origin rpy="0 0 0" xyz="0 0.049 0"/>
    <parent link="br_caster_rotation_link"/>
    <child link="br_caster_l_wheel_link"/>
  </joint>
  <link name="br_caster_l_wheel_link">
    <visual>
      <origin rpy="0 0 0" xyz="0 0 0"/>
      <geometry>
        <mesh filename="/pr2_description/meshes/base_v0/wheel.fbx"/>
      </geometry>
    </visual>
  </link>
  <joint name="br_caster_r_wheel_joint" type="continuous">
    <axis xyz="0 1 0"/>
    <limit effort="7" velocity="15"/>
    <!-- alpha tested effort and velocity limits -->
    <origin rpy="0 0 0" xyz="0 -0.049 0"/>
    <parent link="br_caster_rotation_link"/>
    <child link="br_caster_r_wheel_link"/>
  </joint>
  <link name="br_caster_r_wheel_link">
    <visual>
      <origin rpy="0 0 0" xyz="0 0 0"/>
      <geometry>
        <mesh filename="/pr2_description/meshes/base_v0/wheel.fbx"/>
      </geometry>
    </visual>
  </link>
  <joint name="torso_lift_joint" type="prismatic">
    <axis xyz="0 0 1"/>
    <limit effort="10000" lower="0.0" upper="0.33" velocity="0.013"/>
    <!-- alpha tested velocity and effort limits -->
    <origin rpy="0 0 0" xyz="-0.05 0 0.739675"/>
    <parent link="base_link"/>
    <child link="torso_lift_link"/>
  </joint>
  <link name="torso_lift_link">
    <visual>
      <origin rpy="0 0 0" xyz="0 0 0"/>
      <geometry>
        <mesh filename="/pr2_description/meshes/torso_v0/torso_lift.fbx"/>
      </geometry>
    </visual>
  </link>
  <joint name="l_torso_lift_side_plate_joint" type="fixed">
    <origin xyz="0.0535 0.209285 0.176625"/>
    <!-- location of bottom front bolt hole location -->
    <parent link="torso_lift_link"/>
    <child link="l_torso_lift_side_plate_link"/>
  </joint>
  <link name="l_torso_lift_side_plate_link">
  </link>
  <joint name="r_torso_lift_side_plate_joint" type="fixed">
    <origin xyz="0.0535  -0.209285 0.176625"/>
    <!-- location of bottom front bolt hole location -->
    <parent link="torso_lift_link"/>
    <child link="r_torso_lift_side_plate_link"/>
  </joint>
  <link name="r_torso_lift_side_plate_link">
  </link>
  <!-- actuated motor screw joint -->
  <link name="torso_lift_motor_screw_link">
    <!-- for debugging only
      <visual>
        <origin xyz="0 0 0" rpy="0 0 0" />
        <geometry>
          <box size="0.5 0.7 0.01" />
        </geometry>
      </visual>
      -->
  </link>
  <joint name="torso_lift_motor_screw_joint" type="continuous">
    <origin xyz="-0.15 0.0 0.7"/>
    <axis xyz="0 0 1"/>
    <parent link="base_link"/>
    <child link="torso_lift_motor_screw_link"/>
  </joint>
  <joint name="imu_joint" type="fixed">
    <axis xyz="0 1 0"/>
    <origin rpy="0 3.14159265359 0" xyz="-0.02977 -0.1497 0.164"/>
    <parent link="torso_lift_link"/>
    <child link="imu_link"/>
  </joint>
  <link name="imu_link">
  </link>
  <joint name="head_pan_joint" type="revolute">
    <axis xyz="0 0 1"/>
    <limit effort="2.645" lower="-3.007" upper="3.007" velocity="6"/>
    <!-- alpha tested velocity and effort limits -->
    <origin rpy="0.0 0.0 0.0" xyz="0.0    0.0     0.3915"/>
    <parent link="torso_lift_link"/>
    <child link="head_pan_link"/>
  </joint>
  <link name="head_pan_link">
    <visual>
      <origin rpy="0 0 0 " xyz="0 0 0.0"/>
      <geometry>
        <mesh filename="/pr2_description/meshes/head_v0/head_pan.fbx"/>
      </geometry>
    </visual>
  </link>
  <joint name="head_tilt_joint" type="revolute">
    <axis xyz="0 1 0"/>
    <limit effort="18" lower="-0.471238" upper="1.39626" velocity="5"/>
    <!-- alpha tested velocity and effort limits -->
    <origin rpy="0 0 0" xyz="0.068 0 0"/>
    <parent link="head_pan_link"/>
    <child link="head_tilt_link"/>
  </joint>
  <link name="head_tilt_link">
    <visual>
      <origin rpy="0.0 0.0 0.0" xyz="0 0 0"/>
      <geometry>
        <mesh filename="/pr2_description/meshes/head_v0/head_tilt.fbx"/>
      </geometry>
    </visual>
  </link>
  <!-- Head plate frame -->
  <joint name="head_plate_frame_joint" type="fixed">
    <origin rpy="0 0 0" xyz="0.0232 0 0.0645"/>
    <parent link="head_tilt_link"/>
    <child link="head_plate_frame"/>
  </joint>
  <link name="head_plate_frame">
    <visual>
      <origin rpy="0 0 0" xyz="0 0 0"/>
      <geometry>
        <box size="0.01 0.01 0.01"/>
      </geometry>
    </visual>
  </link>
  <joint name="projector_wg6802418_frame_joint" type="fixed">
    <origin rpy="0 0 0" xyz="0 0.109 0.035"/>
    <parent link="head_plate_frame"/>
    <child link="projector_wg6802418_frame"/>
  </joint>
  <link name="projector_wg6802418_frame">
  </link>
  <joint name="projector_wg6802418_child_frame_joint" type="fixed">
    <origin rpy="0 -1.57079632679 0" xyz="0 0 0"/>
    <parent link="projector_wg6802418_frame"/>
    <child link="projector_wg6802418_child_frame"/>
  </joint>
  <link name="projector_wg6802418_child_frame">
  </link>
  <joint name="sensor_mount_frame_joint" type="fixed">
    <origin rpy="0 0 0" xyz="0.0 0.0 0.0"/>
    <parent link="head_plate_frame"/>
    <child link="sensor_mount_link"/>
  </joint>
  <link name="sensor_mount_link">
    <!-- Should probably get real visuals here at some point -->
    <visual>
      <origin rpy="0 0 0" xyz="0 0 0"/>
      <geometry>
        <box size="0.01 0.01 0.01"/>
      </geometry>
    </visual>
  </link>
  <joint name="high_def_frame_joint" type="fixed">
    <origin rpy="0 0 0" xyz="0.046457 -0.110 0.054600"/>
    <parent link="sensor_mount_link"/>
    <child link="high_def_frame"/>
  </joint>
  <link name="high_def_frame">
  </link>
  <joint name="high_def_optical_frame_joint" type="fixed">
    <origin rpy="-1.57079632679 0.0 -1.57079632679" xyz="0.0            0.0         0.0"/>
    <parent link="high_def_frame"/>
    <child link="high_def_optical_frame"/>
  </joint>
  <link name="high_def_optical_frame">
  </link>
  <!-- Define link to stereo cameras, set origin relative to that -->
  <joint name="double_stereo_frame_joint" type="fixed">
    <origin rpy="0 0 0" xyz="0.0 0.0 0.0"/>
    <parent link="sensor_mount_link"/>
    <child link="double_stereo_link"/>
  </joint>
  <link name="double_stereo_link">
    <!-- Should probably get real visuals here at some point -->
    <visual>
      <origin rpy="0 0 0" xyz="-0.01 0 0.025"/>
      <geometry>
        <box size="0.02 0.12 0.05"/>
      </geometry>
    </visual>
  </link>
  <joint name="wide_stereo_frame_joint" type="fixed">
    <origin rpy="0.0   0.0   0.0" xyz="0.045 0.03 0.0501"/>
    <parent link="double_stereo_link"/>
    <child link="wide_stereo_link"/>
  </joint>
  <!-- camera link is at center of the optical frame, but in x-forward notation -->
  <link name="wide_stereo_link">
  </link>
  <!-- attach optical frame to the camera link -->
  <joint name="wide_stereo_optical_frame_joint" type="fixed">
    <origin rpy="-1.57079632679 0.0 -1.57079632679" xyz="0 0 0"/>
    <!-- rotate frame from x-forward to z-forward camera coords -->
    <parent link="wide_stereo_link"/>
    <child link="wide_stereo_optical_frame"/>
  </joint>
  <!-- optical frame for the stereo camera, with z-forward notation, this is the frame stereo camera images users should refer to -->
  <link name="wide_stereo_optical_frame" type="camera"/>
  <joint name="wide_stereo_l_stereo_camera_frame_joint" type="fixed">
    <origin rpy="0 0 0" xyz="0 0 0"/>
    <parent link="wide_stereo_link"/>
    <child link="wide_stereo_l_stereo_camera_frame"/>
  </joint>
  <link name="wide_stereo_l_stereo_camera_frame">
  </link>
  <joint name="wide_stereo_l_stereo_camera_optical_frame_joint" type="fixed">
    <origin rpy="-1.57079632679 0.0 -1.57079632679" xyz="0 0 0"/>
    <parent link="wide_stereo_l_stereo_camera_frame"/>
    <child link="wide_stereo_l_stereo_camera_optical_frame"/>
  </joint>
  <link name="wide_stereo_l_stereo_camera_optical_frame"/>
  </link>
  <joint name="wide_stereo_r_stereo_camera_optical_frame_joint" type="fixed">
    <origin rpy="-1.57079632679 0.0 -1.57079632679" xyz="0 0 0"/>
    <parent link="wide_stereo_r_stereo_camera_frame"/>
    <child link="wide_stereo_r_stereo_camera_optical_frame"/>
  </joint>
  <link name="wide_stereo_r_stereo_camera_optical_frame"/>
    <turnGravityOff value="true"/>
    <turnGravityOff value="true"/>
  <joint name="narrow_stereo_frame_joint" type="fixed">
    <origin rpy="0.0   0.0   0.0" xyz="0.045 0.06 0.0501"/>
    <parent link="double_stereo_link"/>
    <child link="narrow_stereo_link"/>
  </joint>
  <!-- camera link is at center of the optical frame, but in x-forward notation -->
  <link name="narrow_stereo_link">
  </link>
  <!-- attach optical frame to the camera link -->
  <joint name="narrow_stereo_optical_frame_joint" type="fixed">
    <origin rpy="-1.57079632679 0.0 -1.57079632679" xyz="0 0 0"/>
    <!-- rotate frame from x-forward to z-forward camera coords -->
    <parent link="narrow_stereo_link"/>
    <child link="narrow_stereo_optical_frame"/>
  </joint>
  <!-- optical frame for the stereo camera, with z-forward notation, this is the frame stereo camera images users should refer to -->
  <link name="narrow_stereo_optical_frame" type="camera"/>
  <joint name="narrow_stereo_l_stereo_camera_frame_joint" type="fixed">
    <origin rpy="0 0 0" xyz="0 0 0"/>
    <parent link="narrow_stereo_link"/>
    <child link="narrow_stereo_l_stereo_camera_frame"/>
  </joint>
  <link name="narrow_stereo_l_stereo_camera_frame">
  </link>
  <joint name="narrow_stereo_l_stereo_camera_optical_frame_joint" type="fixed">
    <origin rpy="-1.57079632679 0.0 -1.57079632679" xyz="0 0 0"/>
    <parent link="narrow_stereo_l_stereo_camera_frame"/>
    <child link="narrow_stereo_l_stereo_camera_optical_frame"/>
  </joint>
  <link name="narrow_stereo_l_stereo_camera_optical_frame"/>
  </link>
  <joint name="narrow_stereo_r_stereo_camera_optical_frame_joint" type="fixed">
    <origin rpy="-1.57079632679 0.0 -1.57079632679" xyz="0 0 0"/>
    <parent link="narrow_stereo_r_stereo_camera_frame"/>
    <child link="narrow_stereo_r_stereo_camera_optical_frame"/>
  </joint>
  <link name="narrow_stereo_r_stereo_camera_optical_frame"/>
    <turnGravityOff value="true"/>
    <turnGravityOff value="true"/>
  <!-- Define link to stereo cameras, set origin relative to that -->
  <joint name="laser_tilt_mount_joint" type="revolute">
    <axis xyz="0 1 0"/>
    <limit effort="0.65" lower="-0.7854" upper="1.48353" velocity="10.0"/>
    <!-- alpha tested velocity and effort limits -->
    <origin rpy="0 0 0" xyz="0.1 0 0.235"/>
    <parent link="torso_lift_link"/>
    <child link="laser_tilt_mount_link"/>
  </joint>
  <link name="laser_tilt_mount_link">
    <visual>
      <origin rpy="0 0 0" xyz="0 0 0"/>
      <geometry>
        <mesh filename="/pr2_description/meshes/tilting_laser_v0/tilting_hokuyo.fbx"/>
      </geometry>
    </visual>
  </link>
  <joint name="laser_tilt_joint" type="fixed">
    <axis xyz="0 1 0"/>
    <origin rpy="0 0 0" xyz="0 0 0.03"/>
    <parent link="laser_tilt_mount_link"/>
    <child link="laser_tilt_link"/>
  </joint>
  <link name="laser_tilt_link" type="laser">
  </link>
</robot>
